Workbook
Name AVAIL1: 'DATA ENTRY - JANITORIAL'!$E$2:$E$33
Name AVAIL1: 'DATA ENTRY - RECEIVED'!$E$2:$E$2
Name AVAIL1: 'DATA ENTRY - RELEASED'!$B$2:$B$630
Name AVAIL1: SUMMARY!$B$2:$B$2
Name AVAIL1: 'DATA ENTRY - REQUEST'!$E$2:$E$2
Name Excel_BuiltIn_Print_Area: 'Inventory Supply 2021'!$A$1:$J$150
Name Excel_BuiltIn_Print_Area_1: #REF!
Name Excel_BuiltIn_Print_Area_1_1: #REF!
Name Excel_BuiltIn_Print_Area_1_1_1: #REF!
Name Excel_BuiltIn_Print_Area_1_1_1_1: #REF!
Name Excel_BuiltIn_Print_Area_2: #REF!
Name Excel_BuiltIn_Print_Area_4_1: #REF!
Name REQUEST1: 'DATA ENTRY - REQUEST'!$C:$E
Name REQUEST2: 'DATA ENTRY - REQUEST'!$C:$F
Name SECTION: REFERENCE!$N$3:$N$17
Name STOCKS: 'SUPPLIES SUMMARY'!$A$2:$G$126
Name SUPPLY: REFERENCE!$B$1:$B$114
Name SUPPLY2: REFERENCE!$B$1:$E$114
Name SUPPLY3: 'SUPPLIES SUMMARY'!$A$3:$G$144
Name YEAR2023: REFERENCE!$I:$J
Name YEAR21: REFERENCE!$I$1:$J$348
Name YEAR22: REFERENCE!$I$1:$J$630

Sheet DATA ENTRY - REQUEST
A1: RIS NO | B1: COUNT (Max20) | C1: CODE | D1: REQUEST DATE (MM/DD/YYYY) | E1: DESCRIPTION | F1: QTY | G1: UNIT | H1: STOCK CODE | I1: MONTH
A2: 2023-016 | B2: 1 | C2: =CONCATENATE(A2,B2) -> 2023-0161 | D2: 45149 | E2: Bond copy paper, A4 size,70gsm 500shts/rm | F2: 60 | G2: =IFERROR(VLOOKUP(E2,SUPPLY2,3,0),"-") -> Ream | H2: =IFERROR(VLOOKUP(E2,SUPPLY2,4,0),"-") -> 2276 | I2: =IFERROR(VLOOKUP(D2,YEAR2023,2,0),"-") -> - | L2: =TODAY() -> 46223
A3: 2025-001 | B3: 1 | C3: =CONCATENATE(A3,B3) -> 2025-0011 | D3: 45664 | E3: Bond copy paper, A4 size,70gsm 500shts/rm | F3: 100 | G3: =IFERROR(VLOOKUP(E3,SUPPLY2,3,0),"-") -> Ream | H3: =IFERROR(VLOOKUP(E3,SUPPLY2,4,0),"-") -> 2276 | I3: =IFERROR(VLOOKUP(D3,YEAR2023,2,0),"-") -> 1
A4: 2025-001 | B4: 2 | C4: =CONCATENATE(A4,B4) -> 2025-0012 | D4: 45664 | E4: Bond prem,LEGAL SIZE, 216x330mm,70gsm 500shts/rm | F4: 100 | G4: =IFERROR(VLOOKUP(E4,SUPPLY2,3,0),"-") -> Ream | H4: =IFERROR(VLOOKUP(E4,SUPPLY2,4,0),"-") -> 2067 | I4: =IFERROR(VLOOKUP(D4,YEAR2023,2,0),"-") -> 1
A5: 2025-001 | B5: 3 | C5: =CONCATENATE(A5,B5) -> 2025-0013 | D5: 45664 | E5: Folder - legal size, 36mm thick (14pts) | F5: 100 | G5: =IFERROR(VLOOKUP(E5,SUPPLY2,3,0),"-") -> C | H5: =IFERROR(VLOOKUP(E5,SUPPLY2,4,0),"-") -> 330 | I5: =IFERROR(VLOOKUP(D5,YEAR2023,2,0),"-") -> 1
A6: 2025-001 | B6: 4 | C6: =CONCATENATE(A6,B6) -> 2025-0014 | D6: 45664 | E6: Envelope - document, 10 x 15 | F6: 100 | G6: =IFERROR(VLOOKUP(E6,SUPPLY2,3,0),"-") -> C | H6: =IFERROR(VLOOKUP(E6,SUPPLY2,4,0),"-") -> 46 | I6: =IFERROR(VLOOKUP(D6,YEAR2023,2,0),"-") -> 1
A7: 2025-001 | B7: 5 | C7: =CONCATENATE(A7,B7) -> 2025-0015 | D7: 45664 | E7: Tape - transparent 1 | F7: 100 | G7: =IFERROR(VLOOKUP(E7,SUPPLY2,3,0),"-") -> Roll | H7: =IFERROR(VLOOKUP(E7,SUPPLY2,4,0),"-") -> 301 | I7: =IFERROR(VLOOKUP(D7,YEAR2023,2,0),"-") -> 1
A8: 2025-002 | B8: 1 | C8: =CONCATENATE(A8,B8) -> 2025-0021 | D8: 45687 | E8: Tape - transparent 1 | F8: 100 | G8: =IFERROR(VLOOKUP(E8,SUPPLY2,3,0),"-") -> Roll | H8: =IFERROR(VLOOKUP(E8,SUPPLY2,4,0),"-") -> 301 | I8: =IFERROR(VLOOKUP(D8,YEAR2023,2,0),"-") -> 1
A9: 2025-002 | B9: 2 | C9: =CONCATENATE(A9,B9) -> 2025-0022 | D9: 45687 | E9: Bond copy paper, A4 size,70gsm 500shts/rm | F9: 100 | G9: =IFERROR(VLOOKUP(E9,SUPPLY2,3,0),"-") -> Ream | H9: =IFERROR(VLOOKUP(E9,SUPPLY2,4,0),"-") -> 2276 | I9: =IFERROR(VLOOKUP(D9,YEAR2023,2,0),"-") -> 1
A10: 2025-002 | B10: 3 | C10: =CONCATENATE(A10,B10) -> 2025-0023 | D10: 45687 | E10: Bond prem,LEGAL SIZE, 216x330mm,70gsm 500shts/rm | F10: 100 | G10: =IFERROR(VLOOKUP(E10,SUPPLY2,3,0),"-") -> Ream | H10: =IFERROR(VLOOKUP(E10,SUPPLY2,4,0),"-") -> 2067 | I10: =IFERROR(VLOOKUP(D10,YEAR2023,2,0),"-") -> 1
A11: 2025-002 | B11: 4 | C11: =CONCATENATE(A11,B11) -> 2025-0024 | D11: 45687 | E11: Paste - solid w/ waterwell and applicator | F11: 10 | G11: =IFERROR(VLOOKUP(E11,SUPPLY2,3,0),"-") -> Piece | H11: =IFERROR(VLOOKUP(E11,SUPPLY2,4,0),"-") -> 336 | I11: =IFERROR(VLOOKUP(D11,YEAR2023,2,0),"-") -> 1
A12: 2025-002 | B12: 5 | C12: =CONCATENATE(A12,B12) -> 2025-0025 | D12: 45687 | E12: Ballpoint pen | F12: 100 | G12: =IFERROR(VLOOKUP(E12,SUPPLY2,3,0),"-") -> Piece | H12: =IFERROR(VLOOKUP(E12,SUPPLY2,4,0),"-") -> 337 | I12: =IFERROR(VLOOKUP(D12,YEAR2023,2,0),"-") -> 1
A13: 2025-002 | B13: 6 | C13: =CONCATENATE(A13,B13) -> 2025-0026 | D13: 45687 | E13: Tape - masking 1 | F13: 50 | G13: =IFERROR(VLOOKUP(E13,SUPPLY2,3,0),"-") -> Roll | H13: =IFERROR(VLOOKUP(E13,SUPPLY2,4,0),"-") -> 300 | I13: =IFERROR(VLOOKUP(D13,YEAR2023,2,0),"-") -> 1
A14: 2025-002 | B14: 7 | C14: =CONCATENATE(A14,B14) -> 2025-0027 | D14: 45687 | E14: Correction tape | F14: 10 | G14: =IFERROR(VLOOKUP(E14,SUPPLY2,3,0),"-") -> Piece | H14: =IFERROR(VLOOKUP(E14,SUPPLY2,4,0),"-") -> 1960 | I14: =IFERROR(VLOOKUP(D14,YEAR2023,2,0),"-") -> 1
... A24: 2025-003 | B24: 2 | C24: =CONCATENATE(A24,B24) -> 2025-0032 | D24: 45699 | E24: Staple wire, 5000 pcs | F24: 50 | G24: =IFERROR(VLOOKUP(E24,SUPPLY2,3,0),"-") -> Box | H24: =IFERROR(VLOOKUP(E24,SUPPLY2,4,0),"-") -> 310 | I24: =IFERROR(VLOOKUP(D24,YEAR2023,2,0),"-") -> 2
A25: 2025-003 | B25: 3 | C25: =CONCATENATE(A25,B25) -> 2025-0033 | D25: 45699 | E25: Envelope - document, 10 x 15 | F25: 20 | G25: =IFERROR(VLOOKUP(E25,SUPPLY2,3,0),"-") -> C | H25: =IFERROR(VLOOKUP(E25,SUPPLY2,4,0),"-") -> 46 | I25: =IFERROR(VLOOKUP(D25,YEAR2023,2,0),"-") -> 2
A26: 2025-003 | B26: 4 | C26: =CONCATENATE(A26,B26) -> 2025-0034 | D26: 45699 | E26: Bond copy paper, A4 size,70gsm 500shts/rm | F26: 100 | G26: =IFERROR(VLOOKUP(E26,SUPPLY2,3,0),"-") -> Ream | H26: =IFERROR(VLOOKUP(E26,SUPPLY2,4,0),"-") -> 2276 | I26: =IFERROR(VLOOKUP(D26,YEAR2023,2,0),"-") -> 2
A27: 2025-003 | B27: 5 | C27: =CONCATENATE(A27,B27) -> 2025-0035 | D27: 45699 | E27: Bond prem,LEGAL SIZE, 216x330mm,70gsm 500shts/rm | F27: 100 | G27: =IFERROR(VLOOKUP(E27,SUPPLY2,3,0),"-") -> Ream | H27: =IFERROR(VLOOKUP(E27,SUPPLY2,4,0),"-") -> 2067 | I27: =IFERROR(VLOOKUP(D27,YEAR2023,2,0),"-") -> 2
A28: 2025-003 | B28: 6 | C28: =CONCATENATE(A28,B28) -> 2025-0036 | D28: 45699 | E28: Envelope - document, 10 x 15 | F28: 20 | G28: =IFERROR(VLOOKUP(E28,SUPPLY2,3,0),"-") -> C | H28: =IFERROR(VLOOKUP(E28,SUPPLY2,4,0),"-") -> 46 | I28: =IFERROR(VLOOKUP(D28,YEAR2023,2,0),"-") -> 2
A29: 2025-004 | B29: 1 | C29: =CONCATENATE(A29,B29) -> 2025-0041 | D29: 45707 | E29: Bond copy paper, A4 size,70gsm 500shts/rm | F29: 100 | G29: =IFERROR(VLOOKUP(E29,SUPPLY2,3,0),"-") -> Ream | H29: =IFERROR(VLOOKUP(E29,SUPPLY2,4,0),"-") -> 2276 | I29: =IFERROR(VLOOKUP(D29,YEAR2023,2,0),"-") -> 2
A30: 2025-004 | B30: 2 | C30: =CONCATENATE(A30,B30) -> 2025-0042 | D30: 45707 | E30: Bond prem,LEGAL SIZE, 216x330mm,70gsm 500shts/rm | F30: 100 | G30: =IFERROR(VLOOKUP(E30,SUPPLY2,3,0),"-") -> Ream | H30: =IFERROR(VLOOKUP(E30,SUPPLY2,4,0),"-") -> 2067 | I30: =IFERROR(VLOOKUP(D30,YEAR2023,2,0),"-") -> 2
A31: 2025-004 | B31: 3 | C31: =CONCATENATE(A31,B31) -> 2025-0043 | D31: 45707 | E31: MEMBER DATA CHANGE REQUEST PAGE 1&2 | F31: 100 | G31: =IFERROR(VLOOKUP(E31,SUPPLY2,3,0),"-") -> Ream | H31: =IFERROR(VLOOKUP(E31,SUPPLY2,4,0),"-") -> 0 | I31: =IFERROR(VLOOKUP(D31,YEAR2023,2,0),"-") -> 2
A32: 2025-004 | B32: 4 | C32: =CONCATENATE(A32,B32) -> 2025-0044 | D32: 45707 | E32: ACOP- SURVIVING LEGAL SPOUSE | F32: 100 | G32: =IFERROR(VLOOKUP(E32,SUPPLY2,3,0),"-") -> Ream | H32: =IFERROR(VLOOKUP(E32,SUPPLY2,4,0),"-") -> 0 | I32: =IFERROR(VLOOKUP(D32,YEAR2023,2,0),"-") -> 2
A33: 2025-004 | B33: 5 | C33: =CONCATENATE(A33,B33) -> 2025-0045 | D33: 45707 | E33: ACOP- REPRESENTATIVE PAYEE OF DEPENDENT | F33: 50 | G33: =IFERROR(VLOOKUP(E33,SUPPLY2,3,0),"-") -> Ream | H33: =IFERROR(VLOOKUP(E33,SUPPLY2,4,0),"-") -> 0 | I33: =IFERROR(VLOOKUP(D33,YEAR2023,2,0),"-") -> 2
A34: 2025-004 | B34: 6 | C34: =CONCATENATE(A34,B34) -> 2025-0046 | D34: 45707 | E34: ACOP- RETIREMENT/DISABILITY | F34: 100 | G34: =IFERROR(VLOOKUP(E34,SUPPLY2,3,0),"-") -> Ream | H34: =IFERROR(VLOOKUP(E34,SUPPLY2,4,0),"-") -> 0 | I34: =IFERROR(VLOOKUP(D34,YEAR2023,2,0),"-") -> 2
A35: 2025-004 | B35: 7 | C35: =CONCATENATE(A35,B35) -> 2025-0047 | D35: 45707 | E35: Request/Verification Form new Code | F35: 100 | G35: =IFERROR(VLOOKUP(E35,SUPPLY2,3,0),"-") -> Piece | H35: =IFERROR(VLOOKUP(E35,SUPPLY2,4,0),"-") -> 0 | I35: =IFERROR(VLOOKUP(D35,YEAR2023,2,0),"-") -> 2
A36: 2025-004 | B36: 8 | C36: =CONCATENATE(A36,B36) -> 2025-0048 | D36: 45707 | E36: PAYMENT SLIP-CONTRIBUTION 1 | F36: 100 | G36: =IFERROR(VLOOKUP(E36,SUPPLY2,3,0),"-") -> Ream | H36: =IFERROR(VLOOKUP(E36,SUPPLY2,4,0),"-") -> 2521 | I36: =IFERROR(VLOOKUP(D36,YEAR2023,2,0),"-") -> 2
A37: 2025-004 | B37: 9 | C37: =CONCATENATE(A37,B37) -> 2025-0049 | D37: 45707 | E37: PAYMENT SLIP-MEMBER LOAN | F37: 100 | G37: =IFERROR(VLOOKUP(E37,SUPPLY2,3,0),"-") -> Ream | H37: =IFERROR(VLOOKUP(E37,SUPPLY2,4,0),"-") -> 2576 | I37: =IFERROR(VLOOKUP(D37,YEAR2023,2,0),"-") -> 2
... A82: 2025-006 | B82: 17 | C82: =CONCATENATE(A82,B82) -> 2025-00617 | D82: 45730 | E82: Ballpoint pen | F82: 100 | G82: =IFERROR(VLOOKUP(E82,SUPPLY2,3,0),"-") -> Piece | H82: =IFERROR(VLOOKUP(E82,SUPPLY2,4,0),"-") -> 337 | I82: =IFERROR(VLOOKUP(D82,YEAR2023,2,0),"-") -> 3
A83: 2025-007 | B83: 1 | C83: =CONCATENATE(A83,B83) -> 2025-0071 | D83: 45741 | E83: Bond copy paper, A4 size,70gsm 500shts/rm | F83: 100 | G83: =IFERROR(VLOOKUP(E83,SUPPLY2,3,0),"-") -> Ream | I83: =IFERROR(VLOOKUP(D83,YEAR2023,2,0),"-") -> 3
A84: 2025-007 | B84: 2 | C84: =CONCATENATE(A84,B84) -> 2025-0072 | D84: 45741 | E84: Bond prem,LEGAL SIZE, 216x330mm,70gsm 500shts/rm | F84: 100 | G84: =IFERROR(VLOOKUP(E84,SUPPLY2,3,0),"-") -> Ream | H84: =IFERROR(VLOOKUP(E84,SUPPLY2,4,0),"-") -> 2067 | I84: =IFERROR(VLOOKUP(D84,YEAR2023,2,0),"-") -> 3
A85: 2025-007 | B85: 3 | C85: =CONCATENATE(A85,B85) -> 2025-0073 | D85: 45741 | E85: MEMBER DATA CHANGE REQUEST PAGE 1&2 | F85: 20 | G85: =IFERROR(VLOOKUP(E85,SUPPLY2,3,0),"-") -> Ream | H85: =IFERROR(VLOOKUP(E85,SUPPLY2,4,0),"-") -> 0 | I85: =IFERROR(VLOOKUP(D85,YEAR2023,2,0),"-") -> 3
A86: 2025-007 | B86: 4 | C86: =CONCATENATE(A86,B86) -> 2025-0074 | D86: 45741 | E86: Alcohol, ethyl, 68%-72% | F86: 30 | G86: =IFERROR(VLOOKUP(E86,SUPPLY2,3,0),"-") -> Gallon | H86: =IFERROR(VLOOKUP(E86,SUPPLY2,4,0),"-") -> 2617 | I86: =IFERROR(VLOOKUP(D86,YEAR2023,2,0),"-") -> 3
A87: 2025-007 | B87: 5 | C87: =CONCATENATE(A87,B87) -> 2025-0075 | D87: 45741 | E87: Ballpoint pen | F87: 100 | G87: =IFERROR(VLOOKUP(E87,SUPPLY2,3,0),"-") -> Piece | H87: =IFERROR(VLOOKUP(E87,SUPPLY2,4,0),"-") -> 337 | I87: =IFERROR(VLOOKUP(D87,YEAR2023,2,0),"-") -> 3
A88: 2025-007 | B88: 6 | C88: =CONCATENATE(A88,B88) -> 2025-0076 | D88: 45741 | E88: Folder - legal size, 36mm thick (14pts) | F88: 50 | G88: =IFERROR(VLOOKUP(E88,SUPPLY2,3,0),"-") -> C | H88: =IFERROR(VLOOKUP(E88,SUPPLY2,4,0),"-") -> 330 | I88: =IFERROR(VLOOKUP(D88,YEAR2023,2,0),"-") -> 3
A89: 2025-007 | B89: 7 | C89: =CONCATENATE(A89,B89) -> 2025-0077 | D89: 45741 | E89: Tape - transparent 1 | F89: 100 | G89: =IFERROR(VLOOKUP(E89,SUPPLY2,3,0),"-") -> Roll | H89: =IFERROR(VLOOKUP(E89,SUPPLY2,4,0),"-") -> 301 | I89: =IFERROR(VLOOKUP(D89,YEAR2023,2,0),"-") -> 3
A90: 2025-007 | B90: 8 | C90: =CONCATENATE(A90,B90) -> 2025-0078 | D90: 45741 | E90: Packaging tape 2” | F90: 100 | G90: =IFERROR(VLOOKUP(E90,SUPPLY2,3,0),"-") -> Roll | H90: =IFERROR(VLOOKUP(E90,SUPPLY2,4,0),"-") -> 2537 | I90: =IFERROR(VLOOKUP(D90,YEAR2023,2,0),"-") -> 3
A91: 2025-007 | B91: 9 | C91: =CONCATENATE(A91,B91) -> 2025-0079 | D91: 45741 | E91: Pencil | F91: 20 | G91: =IFERROR(VLOOKUP(E91,SUPPLY2,3,0),"-") -> Piece | H91: =IFERROR(VLOOKUP(E91,SUPPLY2,4,0),"-") -> 0 | I91: =IFERROR(VLOOKUP(D91,YEAR2023,2,0),"-") -> 3
A92: 2025-007 | B92: 10 | C92: =CONCATENATE(A92,B92) -> 2025-00710 | D92: 45741 | E92: Paste - solid w/ waterwell and applicator | F92: 10 | G92: =IFERROR(VLOOKUP(E92,SUPPLY2,3,0),"-") -> Piece | H92: =IFERROR(VLOOKUP(E92,SUPPLY2,4,0),"-") -> 336 | I92: =IFERROR(VLOOKUP(D92,YEAR2023,2,0),"-") -> 3
A93: 2025-007 | B93: 11 | C93: =CONCATENATE(A93,B93) -> 2025-00711 | D93: 45741 | E93: ACOP- SURVIVING LEGAL SPOUSE | F93: 20 | G93: =IFERROR(VLOOKUP(E93,SUPPLY2,3,0),"-") -> Ream | H93: =IFERROR(VLOOKUP(E93,SUPPLY2,4,0),"-") -> 0 | I93: =IFERROR(VLOOKUP(D93,YEAR2023,2,0),"-") -> 3
...

Sheet DATA ENTRY - RECEIVED
A1: RIS NO | B1: COUNT (Max10) | C1: CODE | D1: DATE RECEIVED (MM/DD/YYYY) | E1: DESCRIPTION | F1: STOCKS RECEIVED (QTY) | G1: UNIT | H1: STOCK CODE | I1: MONTH | J1: Column1 | K1: Column2
A2: ='DATA ENTRY - REQUEST'!A2 -> 2023-016 | B2: ='DATA ENTRY - REQUEST'!B2 -> 1 | C2: =Table3[[#This Row],[RIS NO]] & TEXT(Table3[[#This Row],[COUNT (Max10)]], "0;-0") -> 2023-0161 | D2: 45155 | E2: =VLOOKUP(C2,REQUEST1,3,0) -> Bond copy paper, A4 size,70gsm 500shts/rm | F2: 60 | G2: =IFERROR(VLOOKUP(E2,SUPPLY2,3,0),"-") -> Ream | H2: =IFERROR(VLOOKUP(E2,SUPPLY2,4,0),"-") -> 2276 | I2: =IFERROR(VLOOKUP(D2,YEAR2023,2,0),"-") -> -
A3: ='DATA ENTRY - REQUEST'!A3 -> 2025-001 | B3: ='DATA ENTRY - REQUEST'!B3 -> 1 | C3: =Table3[[#This Row],[RIS NO]] & TEXT(Table3[[#This Row],[COUNT (Max10)]], "0;-0") -> 2025-0011 | D3: 45674 | E3: =VLOOKUP(C3,REQUEST1,3,0) -> Bond copy paper, A4 size,70gsm 500shts/rm | F3: 20 | G3: =IFERROR(VLOOKUP(E3,SUPPLY2,3,0),"-") -> Ream | H3: =IFERROR(VLOOKUP(E3,SUPPLY2,4,0),"-") -> 2276 | I3: =IFERROR(VLOOKUP(D3,YEAR2023,2,0),"-") -> 1
A4: ='DATA ENTRY - REQUEST'!A4 -> 2025-001 | B4: ='DATA ENTRY - REQUEST'!B4 -> 2 | C4: =Table3[[#This Row],[RIS NO]] & TEXT(Table3[[#This Row],[COUNT (Max10)]], "0;-0") -> 2025-0012 | D4: 45674 | E4: =VLOOKUP(C4,REQUEST1,3,0) -> Bond prem,LEGAL SIZE, 216x330mm,70gsm 500shts/rm | F4: 20 | G4: =IFERROR(VLOOKUP(E4,SUPPLY2,3,0),"-") -> Ream | H4: =IFERROR(VLOOKUP(E4,SUPPLY2,4,0),"-") -> 2067 | I4: =IFERROR(VLOOKUP(D4,YEAR2023,2,0),"-") -> 1
A5: ='DATA ENTRY - REQUEST'!A5 -> 2025-001 | B5: ='DATA ENTRY - REQUEST'!B5 -> 3 | C5: =Table3[[#This Row],[RIS NO]] & TEXT(Table3[[#This Row],[COUNT (Max10)]], "0;-0") -> 2025-0013 | D5: 45674 | E5: =VLOOKUP(C5,REQUEST1,3,0) -> Folder - legal size, 36mm thick (14pts) | F5: 3 | G5: =IFERROR(VLOOKUP(E5,SUPPLY2,3,0),"-") -> C | H5: =IFERROR(VLOOKUP(E5,SUPPLY2,4,0),"-") -> 330 | I5: =IFERROR(VLOOKUP(D5,YEAR2023,2,0),"-") -> 1
A6: ='DATA ENTRY - REQUEST'!A6 -> 2025-001 | B6: ='DATA ENTRY - REQUEST'!B6 -> 4 | C6: =Table3[[#This Row],[RIS NO]] & TEXT(Table3[[#This Row],[COUNT (Max10)]], "0;-0") -> 2025-0014 | D6: 45699 | E6: =VLOOKUP(C6,REQUEST1,3,0) -> Envelope - document, 10 x 15 | F6: 20 | G6: =IFERROR(VLOOKUP(E6,SUPPLY2,3,0),"-") -> C | H6: =IFERROR(VLOOKUP(E6,SUPPLY2,4,0),"-") -> 46 | I6: =IFERROR(VLOOKUP(D6,YEAR2023,2,0),"-") -> 2
A7: ='DATA ENTRY - REQUEST'!A7 -> 2025-001 | B7: ='DATA ENTRY - REQUEST'!B7 -> 5 | C7: =Table3[[#This Row],[RIS NO]] & TEXT(Table3[[#This Row],[COUNT (Max10)]], "0;-0") -> 2025-0015 | D7: 45699 | E7: =VLOOKUP(C7,REQUEST1,3,0) -> Tape - transparent 1 | F7: 20 | G7: =IFERROR(VLOOKUP(E7,SUPPLY2,3,0),"-") -> Roll | H7: =IFERROR(VLOOKUP(E7,SUPPLY2,4,0),"-") -> 301 | I7: =IFERROR(VLOOKUP(D7,YEAR2023,2,0),"-") -> 2
A8: ='DATA ENTRY - REQUEST'!A8 -> 2025-002 | B8: ='DATA ENTRY - REQUEST'!B8 -> 1 | C8: =Table3[[#This Row],[RIS NO]] & TEXT(Table3[[#This Row],[COUNT (Max10)]], "0;-0") -> 2025-0021 | D8: 45699 | E8: =VLOOKUP(C8,REQUEST1,3,0) -> Tape - transparent 1 | F8: 100 | G8: =IFERROR(VLOOKUP(E8,SUPPLY2,3,0),"-") -> Roll | H8: =IFERROR(VLOOKUP(E8,SUPPLY2,4,0),"-") -> 301 | I8: =IFERROR(VLOOKUP(D8,YEAR2023,2,0),"-") -> 2
A9: ='DATA ENTRY - REQUEST'!A9 -> 2025-002 | B9: ='DATA ENTRY - REQUEST'!B9 -> 2 | C9: =Table3[[#This Row],[RIS NO]] & TEXT(Table3[[#This Row],[COUNT (Max10)]], "0;-0") -> 2025-0022 | D9: 45699 | E9: =VLOOKUP(C9,REQUEST1,3,0) -> Bond copy paper, A4 size,70gsm 500shts/rm | F9: 10 | G9: =IFERROR(VLOOKUP(E9,SUPPLY2,3,0),"-") -> Ream | H9: =IFERROR(VLOOKUP(E9,SUPPLY2,4,0),"-") -> 2276 | I9: =IFERROR(VLOOKUP(D9,YEAR2023,2,0),"-") -> 2
A10: ='DATA ENTRY - REQUEST'!A10 -> 2025-002 | B10: ='DATA ENTRY - REQUEST'!B10 -> 3 | C10: =Table3[[#This Row],[RIS NO]] & TEXT(Table3[[#This Row],[COUNT (Max10)]], "0;-0") -> 2025-0023 | D10: 45699 | E10: =VLOOKUP(C10,REQUEST1,3,0) -> Bond prem,LEGAL SIZE, 216x330mm,70gsm 500shts/rm | F10: 16 | G10: =IFERROR(VLOOKUP(E10,SUPPLY2,3,0),"-") -> Ream | H10: =IFERROR(VLOOKUP(E10,SUPPLY2,4,0),"-") -> 2067 | I10: =IFERROR(VLOOKUP(D10,YEAR2023,2,0),"-") -> 2
A11: ='DATA ENTRY - REQUEST'!A11 -> 2025-002 | B11: ='DATA ENTRY - REQUEST'!B11 -> 4 | C11: =Table3[[#This Row],[RIS NO]] & TEXT(Table3[[#This Row],[COUNT (Max10)]], "0;-0") -> 2025-0024 | D11: 45716 | E11: =VLOOKUP(C11,REQUEST1,3,0) -> Paste - solid w/ waterwell and applicator | F11: 20 | G11: =IFERROR(VLOOKUP(E11,SUPPLY2,3,0),"-") -> Piece | H11: =IFERROR(VLOOKUP(E11,SUPPLY2,4,0),"-") -> 336 | I11: =IFERROR(VLOOKUP(D11,YEAR2023,2,0),"-") -> 2
A12: ='DATA ENTRY - REQUEST'!A12 -> 2025-002 | B12: ='DATA ENTRY - REQUEST'!B12 -> 5 | C12: =Table3[[#This Row],[RIS NO]] & TEXT(Table3[[#This Row],[COUNT (Max10)]], "0;-0") -> 2025-0025 | D12: 45716 | E12: =VLOOKUP(C12,REQUEST1,3,0) -> Ballpoint pen | F12: 20 | G12: =IFERROR(VLOOKUP(E12,SUPPLY2,3,0),"-") -> Piece | H12: =IFERROR(VLOOKUP(E12,SUPPLY2,4,0),"-") -> 337 | I12: =IFERROR(VLOOKUP(D12,YEAR2023,2,0),"-") -> 2
A13: ='DATA ENTRY - REQUEST'!A13 -> 2025-002 | B13: ='DATA ENTRY - REQUEST'!B13 -> 6 | C13: =Table3[[#This Row],[RIS NO]] & TEXT(Table3[[#This Row],[COUNT (Max10)]], "0;-0") -> 2025-0026 | D13: 45716 | E13: =VLOOKUP(C13,REQUEST1,3,0) -> Tape - masking 1 | F13: 20 | G13: =IFERROR(VLOOKUP(E13,SUPPLY2,3,0),"-") -> Roll | H13: =IFERROR(VLOOKUP(E13,SUPPLY2,4,0),"-") -> 300 | I13: =IFERROR(VLOOKUP(D13,YEAR2023,2,0),"-") -> 2
... A21: ='DATA ENTRY - REQUEST'!A21 -> 2025-002 | B21: ='DATA ENTRY - REQUEST'!B21 -> 14 | C21: =Table3[[#This Row],[RIS NO]] & TEXT(Table3[[#This Row],[COUNT (Max10)]], "0;-0") -> 2025-00214 | D21: 45721 | E21: =VLOOKUP(C21,REQUEST1,3,0) -> Folder - legal size, 36mm thick (14pts) | F21: 5 | G21: =IFERROR(VLOOKUP(E21,SUPPLY2,3,0),"-") -> C | H21: =IFERROR(VLOOKUP(E21,SUPPLY2,4,0),"-") -> 330 | I21: =IFERROR(VLOOKUP(D21,YEAR2023,2,0),"-") -> 3
A22: ='DATA ENTRY - REQUEST'!A22 -> 2025-002 | B22: ='DATA ENTRY - REQUEST'!B22 -> 15 | C22: =Table3[[#This Row],[RIS NO]] & TEXT(Table3[[#This Row],[COUNT (Max10)]], "0;-0") -> 2025-00215 | D22: 45721 | E22: =VLOOKUP(C22,REQUEST1,3,0) -> Rubber band - transparent 445 grams | F22: NONE IN STOCK | G22: =IFERROR(VLOOKUP(E22,SUPPLY2,3,0),"-") -> Bag | H22: =IFERROR(VLOOKUP(E22,SUPPLY2,4,0),"-") -> 308 | I22: =IFERROR(VLOOKUP(D22,YEAR2023,2,0),"-") -> 3
A23: ='DATA ENTRY - REQUEST'!A23 -> 2025-003 | B23: ='DATA ENTRY - REQUEST'!B23 -> 1 | C23: =Table3[[#This Row],[RIS NO]] & TEXT(Table3[[#This Row],[COUNT (Max10)]], "0;-0") -> 2025-0031 | D23: 45721 | E23: =VLOOKUP(C23,REQUEST1,3,0) -> Alcohol, ethyl, 68%-72% | F23: NONE IN STOCK | G23: =IFERROR(VLOOKUP(E23,SUPPLY2,3,0),"-") -> Gallon | H23: =IFERROR(VLOOKUP(E23,SUPPLY2,4,0),"-") -> 2617 | I23: =IFERROR(VLOOKUP(D23,YEAR2023,2,0),"-") -> 3
A24: ='DATA ENTRY - REQUEST'!A24 -> 2025-003 | B24: ='DATA ENTRY - REQUEST'!B24 -> 2 | C24: =Table3[[#This Row],[RIS NO]] & TEXT(Table3[[#This Row],[COUNT (Max10)]], "0;-0") -> 2025-0032 | D24: 45721 | E24: =VLOOKUP(C24,REQUEST1,3,0) -> Staple wire, 5000 pcs | F24: NONE IN STOCK | G24: =IFERROR(VLOOKUP(E24,SUPPLY2,3,0),"-") -> Box | H24: =IFERROR(VLOOKUP(E24,SUPPLY2,4,0),"-") -> 310 | I24: =IFERROR(VLOOKUP(D24,YEAR2023,2,0),"-") -> 3
A25: ='DATA ENTRY - REQUEST'!A25 -> 2025-003 | B25: ='DATA ENTRY - REQUEST'!B25 -> 3 | C25: =Table3[[#This Row],[RIS NO]] & TEXT(Table3[[#This Row],[COUNT (Max10)]], "0;-0") -> 2025-0033 | D25: 45721 | E25: =VLOOKUP(C25,REQUEST1,3,0) -> Envelope - document, 10 x 15 | F25: NONE IN STOCK | G25: =IFERROR(VLOOKUP(E25,SUPPLY2,3,0),"-") -> C | H25: =IFERROR(VLOOKUP(E25,SUPPLY2,4,0),"-") -> 46 | I25: =IFERROR(VLOOKUP(D25,YEAR2023,2,0),"-") -> 3
A26: ='DATA ENTRY - REQUEST'!A26 -> 2025-003 | B26: ='DATA ENTRY - REQUEST'!B26 -> 4 | C26: =Table3[[#This Row],[RIS NO]] & TEXT(Table3[[#This Row],[COUNT (Max10)]], "0;-0") -> 2025-0034 | D26: 45721 | E26: =VLOOKUP(C26,REQUEST1,3,0) -> Bond copy paper, A4 size,70gsm 500shts/rm | F26: NONE IN STOCK | G26: =IFERROR(VLOOKUP(E26,SUPPLY2,3,0),"-") -> Ream | H26: =IFERROR(VLOOKUP(E26,SUPPLY2,4,0),"-") -> 2276 | I26: =IFERROR(VLOOKUP(D26,YEAR2023,2,0),"-") -> 3
A27: ='DATA ENTRY - REQUEST'!A27 -> 2025-003 | B27: ='DATA ENTRY - REQUEST'!B27 -> 5 | C27: =Table3[[#This Row],[RIS NO]] & TEXT(Table3[[#This Row],[COUNT (Max10)]], "0;-0") -> 2025-0035 | D27: 45721 | E27: =VLOOKUP(C27,REQUEST1,3,0) -> Bond prem,LEGAL SIZE, 216x330mm,70gsm 500shts/rm | F27: NONE IN STOCK | G27: =IFERROR(VLOOKUP(E27,SUPPLY2,3,0),"-") -> Ream | H27: =IFERROR(VLOOKUP(E27,SUPPLY2,4,0),"-") -> 2067 | I27: =IFERROR(VLOOKUP(D27,YEAR2023,2,0),"-") -> 3
A28: ='DATA ENTRY - REQUEST'!A28 -> 2025-003 | B28: ='DATA ENTRY - REQUEST'!B28 -> 6 | C28: =Table3[[#This Row],[RIS NO]] & TEXT(Table3[[#This Row],[COUNT (Max10)]], "0;-0") -> 2025-0036 | D28: 45721 | E28: =VLOOKUP(C28,REQUEST1,3,0) -> Envelope - document, 10 x 15 | F28: 5 | G28: =IFERROR(VLOOKUP(E28,SUPPLY2,3,0),"-") -> C | H28: =IFERROR(VLOOKUP(E28,SUPPLY2,4,0),"-") -> 46 | I28: =IFERROR(VLOOKUP(D28,YEAR2023,2,0),"-") -> 3
A29: ='DATA ENTRY - REQUEST'!A29 -> 2025-004 | B29: ='DATA ENTRY - REQUEST'!B29 -> 1 | C29: =Table3[[#This Row],[RIS NO]] & TEXT(Table3[[#This Row],[COUNT (Max10)]], "0;-0") -> 2025-0041 | D29: 45721 | E29: =VLOOKUP(C29,REQUEST1,3,0) -> Bond copy paper, A4 size,70gsm 500shts/rm | F29: 20 | G29: =IFERROR(VLOOKUP(E29,SUPPLY2,3,0),"-") -> Ream | H29: =IFERROR(VLOOKUP(E29,SUPPLY2,4,0),"-") -> 2276 | I29: =IFERROR(VLOOKUP(D29,YEAR2023,2,0),"-") -> 3
A30: ='DATA ENTRY - REQUEST'!A30 -> 2025-004 | B30: ='DATA ENTRY - REQUEST'!B30 -> 2 | C30: =Table3[[#This Row],[RIS NO]] & TEXT(Table3[[#This Row],[COUNT (Max10)]], "0;-0") -> 2025-0042 | D30: 45721 | E30: =VLOOKUP(C30,REQUEST1,3,0) -> Bond prem,LEGAL SIZE, 216x330mm,70gsm 500shts/rm | F30: NONE IN STOCK | G30: =IFERROR(VLOOKUP(E30,SUPPLY2,3,0),"-") -> Ream | H30: =IFERROR(VLOOKUP(E30,SUPPLY2,4,0),"-") -> 2067 | I30: =IFERROR(VLOOKUP(D30,YEAR2023,2,0),"-") -> 3
A31: ='DATA ENTRY - REQUEST'!A31 -> 2025-004 | B31: ='DATA ENTRY - REQUEST'!B31 -> 3 | C31: =Table3[[#This Row],[RIS NO]] & TEXT(Table3[[#This Row],[COUNT (Max10)]], "0;-0") -> 2025-0043 | D31: 45721 | E31: =VLOOKUP(C31,REQUEST1,3,0) -> MEMBER DATA CHANGE REQUEST PAGE 1&2 | F31: NONE IN STOCK | G31: =IFERROR(VLOOKUP(E31,SUPPLY2,3,0),"-") -> Ream | H31: =IFERROR(VLOOKUP(E31,SUPPLY2,4,0),"-") -> 0 | I31: =IFERROR(VLOOKUP(D31,YEAR2023,2,0),"-") -> 3
A32: ='DATA ENTRY - REQUEST'!A32 -> 2025-004 | B32: ='DATA ENTRY - REQUEST'!B32 -> 4 | C32: =Table3[[#This Row],[RIS NO]] & TEXT(Table3[[#This Row],[COUNT (Max10)]], "0;-0") -> 2025-0044 | D32: 45721 | E32: =VLOOKUP(C32,REQUEST1,3,0) -> ACOP- SURVIVING LEGAL SPOUSE | F32: NONE IN STOCK | G32: =IFERROR(VLOOKUP(E32,SUPPLY2,3,0),"-") -> Ream | H32: =IFERROR(VLOOKUP(E32,SUPPLY2,4,0),"-") -> 0 | I32: =IFERROR(VLOOKUP(D32,YEAR2023,2,0),"-") -> 3
A33: ='DATA ENTRY - REQUEST'!A33 -> 2025-004 | B33: ='DATA ENTRY - REQUEST'!B33 -> 5 | C33: =Table3[[#This Row],[RIS NO]] & TEXT(Table3[[#This Row],[COUNT (Max10)]], "0;-0") -> 2025-0045 | D33: 45721 | E33: =VLOOKUP(C33,REQUEST1,3,0) -> ACOP- REPRESENTATIVE PAYEE OF DEPENDENT | F33: NONE IN STOCK | G33: =IFERROR(VLOOKUP(E33,SUPPLY2,3,0),"-") -> Ream | H33: =IFERROR(VLOOKUP(E33,SUPPLY2,4,0),"-") -> 0 | I33: =IFERROR(VLOOKUP(D33,YEAR2023,2,0),"-") -> 3
A34: ='DATA ENTRY - REQUEST'!A34 -> 2025-004 | B34: ='DATA ENTRY - REQUEST'!B34 -> 6 | C34: =Table3[[#This Row],[RIS NO]] & TEXT(Table3[[#This Row],[COUNT (Max10)]], "0;-0") -> 2025-0046 | D34: 45721 | E34: =VLOOKUP(C34,REQUEST1,3,0) -> ACOP- RETIREMENT/DISABILITY | F34: NONE IN STOCK | G34: =IFERROR(VLOOKUP(E34,SUPPLY2,3,0),"-") -> Ream | H34: =IFERROR(VLOOKUP(E34,SUPPLY2,4,0),"-") -> 0 | I34: =IFERROR(VLOOKUP(D34,YEAR2023,2,0),"-") -> 3
A35: ='DATA ENTRY - REQUEST'!A35 -> 2025-004 | B35: ='DATA ENTRY - REQUEST'!B35 -> 7 | C35: =Table3[[#This Row],[RIS NO]] & TEXT(Table3[[#This Row],[COUNT (Max10)]], "0;-0") -> 2025-0047 | D35: 45721 | E35: =VLOOKUP(C35,REQUEST1,3,0) -> Request/Verification Form new Code | F35: 20 | G35: =IFERROR(VLOOKUP(E35,SUPPLY2,3,0),"-") -> Piece | H35: =IFERROR(VLOOKUP(E35,SUPPLY2,4,0),"-") -> 0 | I35: =IFERROR(VLOOKUP(D35,YEAR2023,2,0),"-") -> 3
A36: ='DATA ENTRY - REQUEST'!A36 -> 2025-004 | B36: ='DATA ENTRY - REQUEST'!B36 -> 8 | C36: =Table3[[#This Row],[RIS NO]] & TEXT(Table3[[#This Row],[COUNT (Max10)]], "0;-0") -> 2025-0048 | D36: 45721 | E36: =VLOOKUP(C36,REQUEST1,3,0) -> PAYMENT SLIP-CONTRIBUTION 1 | F36: 3 | G36: =IFERROR(VLOOKUP(E36,SUPPLY2,3,0),"-") -> Ream | H36: =IFERROR(VLOOKUP(E36,SUPPLY2,4,0),"-") -> 2521 | I36: =IFERROR(VLOOKUP(D36,YEAR2023,2,0),"-") -> 3
A37: ='DATA ENTRY - REQUEST'!A37 -> 2025-004 | B37: ='DATA ENTRY - REQUEST'!B37 -> 9 | C37: =Table3[[#This Row],[RIS NO]] & TEXT(Table3[[#This Row],[COUNT (Max10)]], "0;-0") -> 2025-0049 | D37: 45730 | E37: =VLOOKUP(C37,REQUEST1,3,0) -> PAYMENT SLIP-MEMBER LOAN | F37: 3 | G37: =IFERROR(VLOOKUP(E37,SUPPLY2,3,0),"-") -> Ream | H37: =IFERROR(VLOOKUP(E37,SUPPLY2,4,0),"-") -> 2576 | I37: =IFERROR(VLOOKUP(D37,YEAR2023,2,0),"-") -> 3
A38: ='DATA ENTRY - REQUEST'!A38 -> 2025-004 | B38: ='DATA ENTRY - REQUEST'!B38 -> 10 | C38: =Table3[[#This Row],[RIS NO]] & TEXT(Table3[[#This Row],[COUNT (Max10)]], "0;-0") -> 2025-00410 | D38: 45730 | E38: =VLOOKUP(C38,REQUEST1,3,0) -> Tape - transparent 1 | F38: 20 | G38: =IFERROR(VLOOKUP(E38,SUPPLY2,3,0),"-") -> Roll | H38: =IFERROR(VLOOKUP(E38,SUPPLY2,4,0),"-") -> 301 | I38: =IFERROR(VLOOKUP(D38,YEAR2023,2,0),"-") -> 3
A39: ='DATA ENTRY - REQUEST'!A39 -> 2025-004 | B39: ='DATA ENTRY - REQUEST'!B39 -> 11 | C39: =Table3[[#This Row],[RIS NO]] & TEXT(Table3[[#This Row],[COUNT (Max10)]], "0;-0") -> 2025-00411 | D39: 45730 | E39: =VLOOKUP(C39,REQUEST1,3,0) -> Correction tape | F39: 2 | G39: =IFERROR(VLOOKUP(E39,SUPPLY2,3,0),"-") -> Piece | H39: =IFERROR(VLOOKUP(E39,SUPPLY2,4,0),"-") -> 1960 | I39: =IFERROR(VLOOKUP(D39,YEAR2023,2,0),"-") -> 3
A40: ='DATA ENTRY - REQUEST'!A40 -> 2025-004 | B40: ='DATA ENTRY - REQUEST'!B40 -> 12 | C40: =Table3[[#This Row],[RIS NO]] & TEXT(Table3[[#This Row],[COUNT (Max10)]], "0;-0") -> 2025-00412 | D40: 45730 | E40: =VLOOKUP(C40,REQUEST1,3,0) -> Envelope - document, 10 x 15 | F40: 2 | G40: =IFERROR(VLOOKUP(E40,SUPPLY2,3,0),"-") -> C | H40: =IFERROR(VLOOKUP(E40,SUPPLY2,4,0),"-") -> 46 | I40: =IFERROR(VLOOKUP(D40,YEAR2023,2,0),"-") -> 3
A41: ='DATA ENTRY - REQUEST'!A41 -> 2025-004 | B41: ='DATA ENTRY - REQUEST'!B41 -> 13 | C41: =Table3[[#This Row],[RIS NO]] & TEXT(Table3[[#This Row],[COUNT (Max10)]], "0;-0") -> 2025-00413 | D41: 45730 | E41: =VLOOKUP(C41,REQUEST1,3,0) -> Folder - legal size, 36mm thick (14pts) | F41: 3 | G41: =IFERROR(VLOOKUP(E41,SUPPLY2,3,0),"-") -> C | H41: =IFERROR(VLOOKUP(E41,SUPPLY2,4,0),"-") -> 330 | I41: =IFERROR(VLOOKUP(D41,YEAR2023,2,0),"-") -> 3
A42: ='DATA ENTRY - REQUEST'!A42 -> 2025-004 | B42: ='DATA ENTRY - REQUEST'!B42 -> 14 | C42: =Table3[[#This Row],[RIS NO]] & TEXT(Table3[[#This Row],[COUNT (Max10)]], "0;-0") -> 2025-00414 | D42: 45730 | E42: =VLOOKUP(C42,REQUEST1,3,0) -> Paper – tissue | F42: 20 | G42: =IFERROR(VLOOKUP(E42,SUPPLY2,3,0),"-") -> Roll | H42: =IFERROR(VLOOKUP(E42,SUPPLY2,4,0),"-") -> 281 | I42: =IFERROR(VLOOKUP(D42,YEAR2023,2,0),"-") -> 3
A43: ='DATA ENTRY - REQUEST'!A43 -> 2025-004 | B43: ='DATA ENTRY - REQUEST'!B43 -> 15 | C43: =Table3[[#This Row],[RIS NO]] & TEXT(Table3[[#This Row],[COUNT (Max10)]], "0;-0") -> 2025-00415 | D43: 45730 | E43: =VLOOKUP(C43,REQUEST1,3,0) -> Rubber band - multicolor, 450 grams | F43: 0 | G43: =IFERROR(VLOOKUP(E43,SUPPLY2,3,0),"-") -> Box | H43: =IFERROR(VLOOKUP(E43,SUPPLY2,4,0),"-") -> 307 | I43: =IFERROR(VLOOKUP(D43,YEAR2023,2,0),"-") -> 3
A44: ='DATA ENTRY - REQUEST'!A44 -> 2025-004 | B44: ='DATA ENTRY - REQUEST'!B44 -> 16 | C44: =Table3[[#This Row],[RIS NO]] & TEXT(Table3[[#This Row],[COUNT (Max10)]], "0;-0") -> 2025-00416 | D44: 45730 | E44: =VLOOKUP(C44,REQUEST1,3,0) -> Rubber band - transparent 445 grams | F44: 0 | G44: =IFERROR(VLOOKUP(E44,SUPPLY2,3,0),"-") -> Bag | H44: =IFERROR(VLOOKUP(E44,SUPPLY2,4,0),"-") -> 308 | I44: =IFERROR(VLOOKUP(D44,YEAR2023,2,0),"-") -> 3
A45: ='DATA ENTRY - REQUEST'!A45 -> 2025-004 | B45: ='DATA ENTRY - REQUEST'!B45 -> 17 | C45: =Table3[[#This Row],[RIS NO]] & TEXT(Table3[[#This Row],[COUNT (Max10)]], "0;-0") -> 2025-00417 | D45: 45730 | E45: =VLOOKUP(C45,REQUEST1,3,0) -> Staple wire, 5000 pcs | F45: 3 | G45: =IFERROR(VLOOKUP(E45,SUPPLY2,3,0),"-") -> Box | H45: =IFERROR(VLOOKUP(E45,SUPPLY2,4,0),"-") -> 310 | I45: =IFERROR(VLOOKUP(D45,YEAR2023,2,0),"-") -> 3
A46: ='DATA ENTRY - REQUEST'!A46 -> 2025-004 | B46: ='DATA ENTRY - REQUEST'!B46 -> 18 | C46: =Table3[[#This Row],[RIS NO]] & TEXT(Table3[[#This Row],[COUNT (Max10)]], "0;-0") -> 2025-00418 | D46: 45730 | E46: =VLOOKUP(C46,REQUEST1,3,0) -> Paste - solid w/ waterwell and applicator | F46: 20 | G46: =IFERROR(VLOOKUP(E46,SUPPLY2,3,0),"-") -> Piece | H46: =IFERROR(VLOOKUP(E46,SUPPLY2,4,0),"-") -> 336 | I46: =IFERROR(VLOOKUP(D46,YEAR2023,2,0),"-") -> 3
... A48: ='DATA ENTRY - REQUEST'!A48 -> 2025-004 | B48: ='DATA ENTRY - REQUEST'!B48 -> 20 | C48: =Table3[[#This Row],[RIS NO]] & TEXT(Table3[[#This Row],[COUNT (Max10)]], "0;-0") -> 2025-00420 | D48: 45730 | E48: =VLOOKUP(C48,REQUEST1,3,0) -> Alcohol, ethyl, 68%-72% | F48: 5 | G48: =IFERROR(VLOOKUP(E48,SUPPLY2,3,0),"-") -> Gallon | H48: =IFERROR(VLOOKUP(E48,SUPPLY2,4,0),"-") -> 2617 | I48: =IFERROR(VLOOKUP(D48,YEAR2023,2,0),"-") -> 3
...

Sheet DATA ENTRY - JANITORIAL
A1: RIS NO | B1: NO (Max10) | C1: REF | D1: REQUEST DATE (MM/DD/YYYY) | E1: DESCRIPTION | F1: QTY | G1: UNIT | H1: STOCK CODE | I1: BALANCE AVAILABLE STOCKS | J1: REQUESTED BY | K1: EMAILED DATE | L1: RECEIPT DATE | M1: NO OF STOCKS (IN) | N1: RELEASING DATE | O1: NO OF STOCKS (OUT) | P1: MONTH
A2: 2022-001 | D2: OLD | E2: SCRUB SPONGE | G2: =IFERROR(VLOOKUP(E2,SUPPLY2,3,0),"-") -> - | H2: =IFERROR(VLOOKUP(E2,SUPPLY2,4,0),"-") -> - | M2: 20 | P2: =IFERROR(VLOOKUP(D2,YEAR21,2,0),"-") -> -
A3: 2022-001 | D3: OLD | E3: BAYGON MULTI INSECT SPRAY | G3: =IFERROR(VLOOKUP(E3,SUPPLY2,3,0),"-") -> - | H3: =IFERROR(VLOOKUP(E3,SUPPLY2,4,0),"-") -> - | M3: 2 | P3: =IFERROR(VLOOKUP(D3,YEAR21,2,0),"-") -> -
A4: 2022-001 | D4: OLD | E4: MULTI PURP CLEANER LIQUID PUREBASICS | G4: =IFERROR(VLOOKUP(E4,SUPPLY2,3,0),"-") -> - | H4: =IFERROR(VLOOKUP(E4,SUPPLY2,4,0),"-") -> - | M4: 4 | P4: =IFERROR(VLOOKUP(D4,YEAR21,2,0),"-") -> -
A5: 2022-001 | D5: OLD | E5: SURF POWDER DETERGENT | G5: =IFERROR(VLOOKUP(E5,SUPPLY2,3,0),"-") -> - | H5: =IFERROR(VLOOKUP(E5,SUPPLY2,4,0),"-") -> - | M5: 12 | P5: =IFERROR(VLOOKUP(D5,YEAR21,2,0),"-") -> -
A6: 2022-001 | D6: OLD | E6: LYSOL TIOLET CLEANER | G6: =IFERROR(VLOOKUP(E6,SUPPLY2,3,0),"-") -> - | H6: =IFERROR(VLOOKUP(E6,SUPPLY2,4,0),"-") -> - | M6: 11 | P6: =IFERROR(VLOOKUP(D6,YEAR21,2,0),"-") -> -
A7: 2022-001 | D7: OLD | E7: HAND LIQUID SOAP (BOT) | G7: =IFERROR(VLOOKUP(E7,SUPPLY2,3,0),"-") -> - | H7: =IFERROR(VLOOKUP(E7,SUPPLY2,4,0),"-") -> - | M7: 4 | P7: =IFERROR(VLOOKUP(D7,YEAR21,2,0),"-") -> -
A8: 2022-001 | D8: OLD | E8: MURIATIC ACID (L) | G8: =IFERROR(VLOOKUP(E8,SUPPLY2,3,0),"-") -> - | H8: =IFERROR(VLOOKUP(E8,SUPPLY2,4,0),"-") -> - | M8: 2 | P8: =IFERROR(VLOOKUP(D8,YEAR21,2,0),"-") -> -
A9: 2022-001 | D9: OLD | E9: MULTI PURP CLEANER LIQUID DOMEX | G9: =IFERROR(VLOOKUP(E9,SUPPLY2,3,0),"-") -> - | H9: =IFERROR(VLOOKUP(E9,SUPPLY2,4,0),"-") -> - | M9: 5 | P9: =IFERROR(VLOOKUP(D9,YEAR21,2,0),"-") -> -
A10: 2022-001 | D10: OLD | E10: ZONROX (GAL) | G10: =IFERROR(VLOOKUP(E10,SUPPLY2,3,0),"-") -> - | H10: =IFERROR(VLOOKUP(E10,SUPPLY2,4,0),"-") -> - | M10: 1 | P10: =IFERROR(VLOOKUP(D10,YEAR21,2,0),"-") -> -
A11: 2022-001 | D11: OLD | E11: MOP HEAD | G11: =IFERROR(VLOOKUP(E11,SUPPLY2,3,0),"-") -> - | H11: =IFERROR(VLOOKUP(E11,SUPPLY2,4,0),"-") -> - | M11: 5 | P11: =IFERROR(VLOOKUP(D11,YEAR21,2,0),"-") -> -
D12: OLD | E12: TRASH BAG XL-XXL | G12: =IFERROR(VLOOKUP(E12,SUPPLY2,3,0),"-") -> - | H12: =IFERROR(VLOOKUP(E12,SUPPLY2,4,0),"-") -> - | M12: 170
D13: OLD | E13: DEODORANT CAKE | G13: =IFERROR(VLOOKUP(E13,SUPPLY2,3,0),"-") -> - | H13: =IFERROR(VLOOKUP(E13,SUPPLY2,4,0),"-") -> - | M13: 30
D14: OLD | E14: MOUSE BAIT | G14: =IFERROR(VLOOKUP(E14,SUPPLY2,3,0),"-") -> - | H14: =IFERROR(VLOOKUP(E14,SUPPLY2,4,0),"-") -> - | M14: 5
D15: 44678 | E15: DEODORANT CAKE | G15: =IFERROR(VLOOKUP(E15,SUPPLY2,3,0),"-") -> - | H15: =IFERROR(VLOOKUP(E15,SUPPLY2,4,0),"-") -> - | M15: 24
D16: 44678 | E16: BAYGON MULTI INSECT SPRAY | G16: =IFERROR(VLOOKUP(E16,SUPPLY2,3,0),"-") -> - | H16: =IFERROR(VLOOKUP(E16,SUPPLY2,4,0),"-") -> - | M16: 6
D17: 44678 | E17: TOILET BOWL CLEANER DOMEX (L) | G17: =IFERROR(VLOOKUP(E17,SUPPLY2,3,0),"-") -> - | H17: =IFERROR(VLOOKUP(E17,SUPPLY2,4,0),"-") -> - | M17: 6
D18: 44678 | E18: AIR FRESHENER (GEL) | G18: =IFERROR(VLOOKUP(E18,SUPPLY2,3,0),"-") -> - | H18: =IFERROR(VLOOKUP(E18,SUPPLY2,4,0),"-") -> - | M18: 12
D19: 44678 | E19: TISSUE (PAPER TOWEL) | G19: =IFERROR(VLOOKUP(E19,SUPPLY2,3,0),"-") -> - | H19: =IFERROR(VLOOKUP(E19,SUPPLY2,4,0),"-") -> - | M19: 6
D20: 44678 | E20: HAND LIQUID SOAP (BOT) | G20: =IFERROR(VLOOKUP(E20,SUPPLY2,3,0),"-") -> - | H20: =IFERROR(VLOOKUP(E20,SUPPLY2,4,0),"-") -> - | M20: 6
D21: 44678 | E21: LYSOL DISINFECTANT SPRAY & AIR FRESHENER/DEODORIZER | G21: =IFERROR(VLOOKUP(E21,SUPPLY2,3,0),"-") -> - | H21: =IFERROR(VLOOKUP(E21,SUPPLY2,4,0),"-") -> - | M21: 6
D22: 44678 | E22: SCRUB SPONGE | G22: =IFERROR(VLOOKUP(E22,SUPPLY2,3,0),"-") -> - | H22: =IFERROR(VLOOKUP(E22,SUPPLY2,4,0),"-") -> - | M22: 6
D23: 44678 | E23: CAR FRESHENER | G23: =IFERROR(VLOOKUP(E23,SUPPLY2,3,0),"-") -> - | H23: =IFERROR(VLOOKUP(E23,SUPPLY2,4,0),"-") -> - | M23: 4
D24: 44678 | E24: DISHWASHING LIQUID (L) | G24: =IFERROR(VLOOKUP(E24,SUPPLY2,3,0),"-") -> - | H24: =IFERROR(VLOOKUP(E24,SUPPLY2,4,0),"-") -> - | M24: 3
D25: 44678 | E25: ZONROX (GAL) | G25: =IFERROR(VLOOKUP(E25,SUPPLY2,3,0),"-") -> - | H25: =IFERROR(VLOOKUP(E25,SUPPLY2,4,0),"-") -> - | M25: 4
D26: 44678 | E26: RUG | G26: =IFERROR(VLOOKUP(E26,SUPPLY2,3,0),"-") -> - | H26: =IFERROR(VLOOKUP(E26,SUPPLY2,4,0),"-") -> - | M26: 9
D27: 44678 | E27: SOFT BROOM | G27: =IFERROR(VLOOKUP(E27,SUPPLY2,3,0),"-") -> - | H27: =IFERROR(VLOOKUP(E27,SUPPLY2,4,0),"-") -> - | M27: 2
D28: OLD | E28: DISINFECTANT & CLEANING SOLUTION (GAL) | G28: =IFERROR(VLOOKUP(E28,SUPPLY2,3,0),"-") -> - | H28: =IFERROR(VLOOKUP(E28,SUPPLY2,4,0),"-") -> - | M28: 10
D29: OLD | E29: HAND SANITIZER (GAL) | G29: =IFERROR(VLOOKUP(E29,SUPPLY2,3,0),"-") -> - | H29: =IFERROR(VLOOKUP(E29,SUPPLY2,4,0),"-") -> - | M29: 4
D30: OLD | E30: ALCOHOL ETHYL (GAL) | G30: =IFERROR(VLOOKUP(E30,SUPPLY2,3,0),"-") -> - | H30: =IFERROR(VLOOKUP(E30,SUPPLY2,4,0),"-") -> - | M30: 6
G31: =IFERROR(VLOOKUP(E31,SUPPLY2,3,0),"-") -> - | H31: =IFERROR(VLOOKUP(E31,SUPPLY2,4,0),"-") -> -
G32: =IFERROR(VLOOKUP(E32,SUPPLY2,3,0),"-") -> - | H32: =IFERROR(VLOOKUP(E32,SUPPLY2,4,0),"-") -> -
G33: =IFERROR(VLOOKUP(E33,SUPPLY2,3,0),"-") -> - | H33: =IFERROR(VLOOKUP(E33,SUPPLY2,4,0),"-") -> -
G34: =IFERROR(VLOOKUP(E34,SUPPLY2,3,0),"-") -> - | H34: =IFERROR(VLOOKUP(E34,SUPPLY2,4,0),"-") -> - | P34: =IFERROR(VLOOKUP(D34,YEAR21,2,0),"-") -> -
G35: =IFERROR(VLOOKUP(E35,SUPPLY2,3,0),"-") -> - | H35: =IFERROR(VLOOKUP(E35,SUPPLY2,4,0),"-") -> - | P35: =IFERROR(VLOOKUP(D35,YEAR21,2,0),"-") -> -
G36: =IFERROR(VLOOKUP(E36,SUPPLY2,3,0),"-") -> - | H36: =IFERROR(VLOOKUP(E36,SUPPLY2,4,0),"-") -> - | P36: =IFERROR(VLOOKUP(D36,YEAR21,2,0),"-") -> -
G37: =IFERROR(VLOOKUP(E37,SUPPLY2,3,0),"-") -> - | H37: =IFERROR(VLOOKUP(E37,SUPPLY2,4,0),"-") -> - | P37: =IFERROR(VLOOKUP(D37,YEAR21,2,0),"-") -> -
D38: 44678 | E38: TISSUE (PAPER TOWEL) | F38: 1 | G38: =IFERROR(VLOOKUP(E38,SUPPLY2,3,0),"-") -> - | H38: =IFERROR(VLOOKUP(E38,SUPPLY2,4,0),"-") -> - | I38: =IFERROR(VLOOKUP(H38,'SUPPLIES SUMMARY'!A$147:G$180,7,0),"-") -> - | J38: RHODA | N38: 44678 | O38: =F38 -> 1 | P38: =IFERROR(VLOOKUP(D38,YEAR21,2,0),"-") -> -
D39: 44679 | E39: CAR FRESHENER | F39: 1 | G39: =IFERROR(VLOOKUP(E39,SUPPLY2,3,0),"-") -> - | H39: =IFERROR(VLOOKUP(E39,SUPPLY2,4,0),"-") -> - | I39: =IFERROR(VLOOKUP(H39,'SUPPLIES SUMMARY'!A$147:G$180,7,0),"-") -> - | J39: MARTIN | N39: 44679 | O39: =F39 -> 1 | P39: =IFERROR(VLOOKUP(D39,YEAR21,2,0),"-") -> -
D40: 44679 | E40: AIR FRESHENER (GEL) | F40: 2 | G40: =IFERROR(VLOOKUP(E40,SUPPLY2,3,0),"-") -> - | H40: =IFERROR(VLOOKUP(E40,SUPPLY2,4,0),"-") -> - | I40: =IFERROR(VLOOKUP(H40,'SUPPLIES SUMMARY'!A$147:G$180,7,0),"-") -> - | J40: RHODA | N40: 44679 | O40: =F40 -> 2 | P40: =IFERROR(VLOOKUP(D40,YEAR21,2,0),"-") -> -
...

Sheet Sheet1
C1: AIR FRESHENER (GEL)
C2: BAYGON MULTI INSECT SPRAY
C3: BROOM BRUSH
C4: BROOM NYLON
C5: BRUSH
C6: CAR FRESHENER
C7: DECLOGGER
C8: DEODORANT CAKE
C9: DISHWASHING LIQUID (L)
C10: DISINFECTANT MAT
C11: DUST PAN
C12: HAND LIQUID SOAP (BOT)
... C46: TELLERING

Sheet DATA ENTRY - RELEASED
A1: DATE RELEASED (MM/DD/YYYY) | B1: DESCRIPTION | C1: STOCKS RELEASED (QTY) | D1: UNIT | E1: STOCK CODE | F1: REQUESTED BY medical | G1: MONTH | H1: Column1
A2: 45660 | B2: Bond copy paper, A4 size,70gsm 500shts/rm | C2: 3 | D2: =IFERROR(VLOOKUP(B2,SUPPLY2,3,0),"-") -> Ream | E2: =IFERROR(VLOOKUP(B2,SUPPLY2,4,0),"-") -> 2276 | F2: ADMIN | G2: =IFERROR(VLOOKUP(A2,YEAR2023,2,0),"-") -> 1
A3: 45660 | B3: Bond prem,LEGAL SIZE, 216x330mm,70gsm 500shts/rm | C3: 3 | D3: =IFERROR(VLOOKUP(B3,SUPPLY2,3,0),"-") -> Ream | E3: =IFERROR(VLOOKUP(B3,SUPPLY2,4,0),"-") -> 2067 | F3: ADMIN | G3: =IFERROR(VLOOKUP(A3,YEAR2023,2,0),"-") -> 1
A4: 45692 | B4: Bond copy paper, A4 size,70gsm 500shts/rm | C4: 1 | D4: =IFERROR(VLOOKUP(B4,SUPPLY2,3,0),"-") -> Ream | E4: =IFERROR(VLOOKUP(B4,SUPPLY2,4,0),"-") -> 2276 | F4: TELLERING | G4: =IFERROR(VLOOKUP(A4,YEAR2023,2,0),"-") -> 2
A5: 45692 | B5: Bond prem,LEGAL SIZE, 216x330mm,70gsm 500shts/rm | C5: 1 | D5: =IFERROR(VLOOKUP(B5,SUPPLY2,3,0),"-") -> Ream | E5: =IFERROR(VLOOKUP(B5,SUPPLY2,4,0),"-") -> 2067 | F5: ADMIN | G5: =IFERROR(VLOOKUP(A5,YEAR2023,2,0),"-") -> 2
A6: 45695 | B6: Bond copy paper, A4 size,70gsm 500shts/rm | C6: 1 | D6: =IFERROR(VLOOKUP(B6,SUPPLY2,3,0),"-") -> Ream | E6: =IFERROR(VLOOKUP(B6,SUPPLY2,4,0),"-") -> 2276 | F6: MSS-ECS | G6: =IFERROR(VLOOKUP(A6,YEAR2023,2,0),"-") -> 2
A7: 45695 | B7: Bond prem,LEGAL SIZE, 216x330mm,70gsm 500shts/rm | C7: 1 | D7: =IFERROR(VLOOKUP(B7,SUPPLY2,3,0),"-") -> Ream | E7: =IFERROR(VLOOKUP(B7,SUPPLY2,4,0),"-") -> 2067 | F7: MSS-ECS | G7: =IFERROR(VLOOKUP(A7,YEAR2023,2,0),"-") -> 2
A8: 45695 | B8: Bond copy paper, A4 size,70gsm 500shts/rm | C8: 2 | D8: =IFERROR(VLOOKUP(B8,SUPPLY2,3,0),"-") -> Ream | E8: =IFERROR(VLOOKUP(B8,SUPPLY2,4,0),"-") -> 2276 | F8: ADMIN | G8: =IFERROR(VLOOKUP(A8,YEAR2023,2,0),"-") -> 2
A9: 45695 | B9: Bond prem,LEGAL SIZE, 216x330mm,70gsm 500shts/rm | C9: 2 | D9: =IFERROR(VLOOKUP(B9,SUPPLY2,3,0),"-") -> Ream | E9: =IFERROR(VLOOKUP(B9,SUPPLY2,4,0),"-") -> 2067 | F9: ADMIN | G9: =IFERROR(VLOOKUP(A9,YEAR2023,2,0),"-") -> 2
A10: 45701 | B10: Bond prem,LEGAL SIZE, 216x330mm,70gsm 500shts/rm | C10: 2 | D10: =IFERROR(VLOOKUP(B10,SUPPLY2,3,0),"-") -> Ream | E10: =IFERROR(VLOOKUP(B10,SUPPLY2,4,0),"-") -> 2067 | F10: MSS | G10: =IFERROR(VLOOKUP(A10,YEAR2023,2,0),"-") -> 2
A11: 45701 | B11: Bond copy paper, A4 size,70gsm 500shts/rm | C11: 2 | D11: =IFERROR(VLOOKUP(B11,SUPPLY2,3,0),"-") -> Ream | E11: =IFERROR(VLOOKUP(B11,SUPPLY2,4,0),"-") -> 2276 | F11: MSS | G11: =IFERROR(VLOOKUP(A11,YEAR2023,2,0),"-") -> 2
A12: 45706 | B12: Bond copy paper, A4 size,70gsm 500shts/rm | C12: 2 | D12: =IFERROR(VLOOKUP(B12,SUPPLY2,3,0),"-") -> Ream | E12: =IFERROR(VLOOKUP(B12,SUPPLY2,4,0),"-") -> 2276 | F12: ADMIN | G12: =IFERROR(VLOOKUP(A12,YEAR2023,2,0),"-") -> 2
A13: 45706 | B13: Bond prem,LEGAL SIZE, 216x330mm,70gsm 500shts/rm | C13: 2 | D13: =IFERROR(VLOOKUP(B13,SUPPLY2,3,0),"-") -> Ream | E13: =IFERROR(VLOOKUP(B13,SUPPLY2,4,0),"-") -> 2067 | F13: ADMIN | G13: =IFERROR(VLOOKUP(A13,YEAR2023,2,0),"-") -> 2
... A38: 45784 | B38: Tape - masking 1 | C38: 15 | D38: =IFERROR(VLOOKUP(B38,SUPPLY2,3,0),"-") -> Roll | E38: =IFERROR(VLOOKUP(B38,SUPPLY2,4,0),"-") -> 300 | F38: ADMIN | G38: =IFERROR(VLOOKUP(A38,YEAR2023,2,0),"-") -> 5
A39: 45785 | B39: Staple wire, 5000 pcs | C39: 298 | D39: =IFERROR(VLOOKUP(B39,SUPPLY2,3,0),"-") -> Box | E39: =IFERROR(VLOOKUP(B40,SUPPLY2,4,0),"-") -> 281 | F39: ADMIN | G39: =IFERROR(VLOOKUP(A39,YEAR2023,2,0),"-") -> 5
A40: 45796 | B40: Paper – tissue | C40: 132 | D40: =IFERROR(VLOOKUP(B40,SUPPLY2,3,0),"-") -> Roll | E40: =IFERROR(VLOOKUP(B40,SUPPLY2,4,0),"-") -> 281 | F40: ADMIN | G40: =IFERROR(VLOOKUP(A40,YEAR2023,2,0),"-") -> 5
A41: 45799 | B41: Packaging tape 2” | C41: 31 | D41: =IFERROR(VLOOKUP(B41,SUPPLY2,3,0),"-") -> Roll | E41: =IFERROR(VLOOKUP(B41,SUPPLY2,4,0),"-") -> 2537 | F41: ADMIN | G41: =IFERROR(VLOOKUP(A41,YEAR2023,2,0),"-") -> 5
A42: 45814 | B42: Ballpoint pen | C42: 50 | D42: =IFERROR(VLOOKUP(B42,SUPPLY2,3,0),"-") -> Piece | E42: =IFERROR(VLOOKUP(B42,SUPPLY2,4,0),"-") -> 337 | F42: ADMIN | G42: =IFERROR(VLOOKUP(A42,YEAR2023,2,0),"-") -> 6
A43: 45828 | B43: Alcohol, ethyl, 68%-72% | C43: 40 | D43: =IFERROR(VLOOKUP(B43,SUPPLY2,3,0),"-") -> Gallon | E43: =IFERROR(VLOOKUP(B43,SUPPLY2,4,0),"-") -> 2617 | F43: ADMIN | G43: =IFERROR(VLOOKUP(A43,YEAR2023,2,0),"-") -> 6
A44: 45828 | B44: Bond prem,LEGAL SIZE, 216x330mm,70gsm 500shts/rm | C44: 3 | D44: =IFERROR(VLOOKUP(B44,SUPPLY2,3,0),"-") -> Ream | E44: =IFERROR(VLOOKUP(B44,SUPPLY2,4,0),"-") -> 2067 | F44: MSS | G44: =IFERROR(VLOOKUP(A44,YEAR2023,2,0),"-") -> 6
A45: 45834 | B45: Bond copy paper, A4 size,70gsm 500shts/rm | C45: 4 | D45: =IFERROR(VLOOKUP(B45,SUPPLY2,3,0),"-") -> Ream | E45: =IFERROR(VLOOKUP(B45,SUPPLY2,4,0),"-") -> 2276 | F45: KAPATAGAN SO | G45: =IFERROR(VLOOKUP(A45,YEAR2023,2,0),"-") -> 6
A46: 45847 | B46: Tape - masking 1 | C46: 3 | D46: =IFERROR(VLOOKUP(B46,SUPPLY2,3,0),"-") -> Roll | E46: =IFERROR(VLOOKUP(B46,SUPPLY2,4,0),"-") -> 300 | F46: MSS | G46: =IFERROR(VLOOKUP(A46,YEAR2023,2,0),"-") -> 7
A47: 45849 | B47: Folder - legal size, 36mm thick (14pts) | C47: 29 | D47: =IFERROR(VLOOKUP(B47,SUPPLY2,3,0),"-") -> C | E47: =IFERROR(VLOOKUP(B47,SUPPLY2,4,0),"-") -> 330 | F47: MSS | G47: =IFERROR(VLOOKUP(A47,YEAR2023,2,0),"-") -> 7
A48: 45849 | B48: Paper – tissue | C48: 4 | D48: =IFERROR(VLOOKUP(B48,SUPPLY2,3,0),"-") -> Roll | E48: =IFERROR(VLOOKUP(B48,SUPPLY2,4,0),"-") -> 281 | F48: ADMIN | G48: =IFERROR(VLOOKUP(A48,YEAR2023,2,0),"-") -> 7
A49: 45849 | B49: Request/Verification Form new Code | C49: 100 | D49: =IFERROR(VLOOKUP(B49,SUPPLY2,3,0),"-") -> Piece | E49: =IFERROR(VLOOKUP(B49,SUPPLY2,4,0),"-") -> 0 | F49: MSS | G49: =IFERROR(VLOOKUP(A49,YEAR2023,2,0),"-") -> 7
A50: 45849 | B50: Alcohol, ethyl, 68%-72% (500ml) | C50: 8 | D50: =IFERROR(VLOOKUP(B50,SUPPLY2,3,0),"-") -> Bottle | E50: =IFERROR(VLOOKUP(B50,SUPPLY2,4,0),"-") -> 2618 | F50: MSS | G50: =IFERROR(VLOOKUP(A50,YEAR2023,2,0),"-") -> 7
A51: 45849 | B51: Envelope - document, 10 x 15 | C51: 10 | D51: =IFERROR(VLOOKUP(B51,SUPPLY2,3,0),"-") -> C | E51: =IFERROR(VLOOKUP(B51,SUPPLY2,4,0),"-") -> 46 | F51: MSS | G51: =IFERROR(VLOOKUP(A51,YEAR2023,2,0),"-") -> 7
... A112: 45964 | B112: E4-PAGE 1-MEMBER DATA CHANGE PAGE 1 | C112: 10 | D112: =IFERROR(VLOOKUP(B112,SUPPLY2,3,0),"-") -> - | E112: =IFERROR(VLOOKUP(B112,SUPPLY2,4,0),"-") -> - | F112: MSS | G112: =IFERROR(VLOOKUP(A112,YEAR2023,2,0),"-") -> 11
A113: 45966 | B113: E4-PAGE 1-MEMBER DATA CHANGE PAGE 1 | C113: 100 | D113: pieces | E113: =IFERROR(VLOOKUP(B113,SUPPLY2,4,0),"-") -> - | F113: MSS | G113: =IFERROR(VLOOKUP(A113,YEAR2023,2,0),"-") -> 11
A114: 45966 | B114: Bond copy paper, A4 size,70gsm 500shts/rm | C114: 2 | D114: =IFERROR(VLOOKUP(B114,SUPPLY2,3,0),"-") -> Ream | E114: =IFERROR(VLOOKUP(B114,SUPPLY2,4,0),"-") -> 2276 | F114: ADMIN | G114: =IFERROR(VLOOKUP(A114,YEAR2023,2,0),"-") -> 11
A115: 45968 | B115: Thermal paper for set 80 x 30mm | C115: 4 | D115: =IFERROR(VLOOKUP(B115,SUPPLY2,3,0),"-") -> Roll | E115: =IFERROR(VLOOKUP(B115,SUPPLY2,4,0),"-") -> 2629 | F115: MSS | G115: =IFERROR(VLOOKUP(A115,YEAR2023,2,0),"-") -> 11
A116: 45971 | B116: Bond copy paper, A4 size,70gsm 500shts/rm | C116: 2 | D116: =IFERROR(VLOOKUP(B116,SUPPLY2,3,0),"-") -> Ream | E116: =IFERROR(VLOOKUP(B116,SUPPLY2,4,0),"-") -> 2276 | F116: ADMIN | G116: =IFERROR(VLOOKUP(A116,YEAR2023,2,0),"-") -> 11
A117: 45971 | B117: MEMBER DATA CHANGE REQUEST PAGE 1&2 | C117: 100 | D117: =IFERROR(VLOOKUP(B117,SUPPLY2,3,0),"-") -> Ream | E117: =IFERROR(VLOOKUP(B117,SUPPLY2,4,0),"-") -> 0 | F117: MSS | G117: =IFERROR(VLOOKUP(A117,YEAR2023,2,0),"-") -> 11
A118: 45971 | B118: Pencil | C118: 1 | D118: =IFERROR(VLOOKUP(B118,SUPPLY2,3,0),"-") -> Piece | E118: =IFERROR(VLOOKUP(B118,SUPPLY2,4,0),"-") -> 0 | F118: MSS-JGT | G118: =IFERROR(VLOOKUP(A118,YEAR2023,2,0),"-") -> 11
A119: 45971 | B119: Folder - legal size, 36mm thick (14pts) | C119: 10 | D119: =IFERROR(VLOOKUP(B119,SUPPLY2,3,0),"-") -> C | E119: =IFERROR(VLOOKUP(B119,SUPPLY2,4,0),"-") -> 330 | F119: AMS | G119: =IFERROR(VLOOKUP(A119,YEAR2023,2,0),"-") -> 11
A120: 45971 | B120: Request/Verification Form new Code, E4 form | C120: 100 | D120: =IFERROR(VLOOKUP(B120,SUPPLY2,3,0),"-") -> - | E120: =IFERROR(VLOOKUP(B120,SUPPLY2,4,0),"-") -> - | F120: mss | G120: =IFERROR(VLOOKUP(A120,YEAR2023,2,0),"-") -> 11
A121: 45971 | B121: PAYMENT SLIP-CONTRIBUTION 1 | C121: 100 | D121: pieces | E121: =IFERROR(VLOOKUP(B121,SUPPLY2,4,0),"-") -> 2521 | F121: MSS | G121: =IFERROR(VLOOKUP(A121,YEAR2023,2,0),"-") -> 11
A122: 45971 | B122: ACOP- SURVIVING LEGAL SPOUSE | C122: 100 | D122: pieces | E122: =IFERROR(VLOOKUP(B122,SUPPLY2,4,0),"-") -> 0 | F122: MSS | G122: =IFERROR(VLOOKUP(A122,YEAR2023,2,0),"-") -> 11
A123: 45972 | B123: paper cup | C123: 1 | D123: pack | E123: =IFERROR(VLOOKUP(B123,SUPPLY2,4,0),"-") -> - | F123: ADMIN | G123: =IFERROR(VLOOKUP(A123,YEAR2023,2,0),"-") -> 11
A124: 45972 | B124: Alcohol, ethyl, 68%-72% (500ml) | C124: 2 | D124: =IFERROR(VLOOKUP(B124,SUPPLY2,3,0),"-") -> Bottle | E124: =IFERROR(VLOOKUP(B124,SUPPLY2,4,0),"-") -> 2618 | F124: ADMIN | G124: =IFERROR(VLOOKUP(A124,YEAR2023,2,0),"-") -> 11
...

Sheet SUMMARY
A1: DATE TODAY (MM/DD/YYYY) | B1: DESCRIPTION | C1: BEG BALANCE (QTY) | D1: TOTAL STOCKS RECEIVED (QTY) | E1: TOTAL STOCKS RELEASED (QTY) | F1: ENDING BALANCE (QTY) | G1: UNIT | H1: STOCK CODE | I1: MONTH | L1: ACTUAL
A2: =TODAY() -> 46223 | B2: Bond copy paper, A4 size,70gsm 500shts/rm | C2: 9 | D2: =SUMIFS('DATA ENTRY - RECEIVED'!F:F,'DATA ENTRY - RECEIVED'!E:E,"=Bond copy paper, A4 size,70gsm 500shts/rm") -> 295 | E2: =SUMIFS('DATA ENTRY - RELEASED'!C:C,'DATA ENTRY - RELEASED'!B:B,"=Bond copy paper, A4 size,70gsm 500shts/rm") -> 212 | F2: =Table26[[#This Row],[BEG BALANCE (QTY)]]+Table26[[#This Row],[TOTAL STOCKS RECEIVED (QTY)]]-Table26[[#This Row],[TOTAL STOCKS RELEASED (QTY)]] -> 92 | G2: =IFERROR(VLOOKUP(B2,SUPPLY2,3,0),"-") -> Ream | H2: =IFERROR(VLOOKUP(B2,SUPPLY2,4,0),"-") -> 2276 | I2: =IFERROR(VLOOKUP(A2,YEAR2023,2,0),"-") -> 0 | L2: 97
A3: =TODAY() -> 46223 | B3: Bond prem,LEGAL SIZE, 216x330mm,70gsm 500shts/rm | C3: 241 | D3: =SUMIFS('DATA ENTRY - RECEIVED'!F:F,'DATA ENTRY - RECEIVED'!E:E,"=Bond prem,LEGAL SIZE, 216x330mm,70gsm 500shts/rm") -> 151 | E3: =SUMIFS('DATA ENTRY - RELEASED'!C:C,'DATA ENTRY - RELEASED'!B:B,"=Bond prem,LEGAL SIZE, 216x330mm,70gsm 500shts/rm") -> 90 | F3: =Table26[[#This Row],[BEG BALANCE (QTY)]]+Table26[[#This Row],[TOTAL STOCKS RECEIVED (QTY)]]-Table26[[#This Row],[TOTAL STOCKS RELEASED (QTY)]] -> 302 | G3: =IFERROR(VLOOKUP(B3,SUPPLY2,3,0),"-") -> Ream | H3: =IFERROR(VLOOKUP(B3,SUPPLY2,4,0),"-") -> 2067 | I3: =IFERROR(VLOOKUP(A3,YEAR2023,2,0),"-") -> 0 | L3: 302
A4: =TODAY() -> 46223 | B4: Carbon film, legal | C4: 51 | D4: =SUMIFS('DATA ENTRY - RECEIVED'!F:F,'DATA ENTRY - RECEIVED'!E:E,"=Carbon film, legal") -> 0 | E4: =SUMIFS('DATA ENTRY - RELEASED'!C:C,'DATA ENTRY - RELEASED'!B:B,"=Carbon film, legal") -> 0 | F4: =Table26[[#This Row],[BEG BALANCE (QTY)]]+Table26[[#This Row],[TOTAL STOCKS RECEIVED (QTY)]]-Table26[[#This Row],[TOTAL STOCKS RELEASED (QTY)]] -> 51 | G4: =IFERROR(VLOOKUP(B4,SUPPLY2,3,0),"-") -> Box | H4: =IFERROR(VLOOKUP(B4,SUPPLY2,4,0),"-") -> 2634 | I4: =IFERROR(VLOOKUP(A4,YEAR2023,2,0),"-") -> 0 | L4: 51
A5: =TODAY() -> 46223 | B5: Cartolina - white, 22-1/2 x 28-1/2 | D5: =SUMIFS('DATA ENTRY - RECEIVED'!F:F,'DATA ENTRY - RECEIVED'!E:E,"=Cartolina - white, 22-1/2 x 28-1/2") -> 0 | E5: =SUMIFS('DATA ENTRY - RELEASED'!C:C,'DATA ENTRY - RELEASED'!B:B,"=Cartolina - white, 22-1/2 x 28-1/2") -> 0 | F5: =Table26[[#This Row],[BEG BALANCE (QTY)]]+Table26[[#This Row],[TOTAL STOCKS RECEIVED (QTY)]]-Table26[[#This Row],[TOTAL STOCKS RELEASED (QTY)]] -> 0 | G5: =IFERROR(VLOOKUP(B5,SUPPLY2,3,0),"-") -> Piece | H5: =IFERROR(VLOOKUP(B5,SUPPLY2,4,0),"-") -> 5 | I5: =IFERROR(VLOOKUP(A5,YEAR2023,2,0),"-") -> 0
A6: =TODAY() -> 46223 | B6: Envelope - document, 10 x 15 | C6: 0 | D6: =SUMIFS('DATA ENTRY - RECEIVED'!F:F,'DATA ENTRY - RECEIVED'!E:E,"=Envelope - document, 10 x 15") -> 132 | E6: =SUMIFS('DATA ENTRY - RELEASED'!C:C,'DATA ENTRY - RELEASED'!B:B,"=Envelope - document, 10 x 15")*(0.01) -> 1.52 | F6: =Table26[[#This Row],[BEG BALANCE (QTY)]]+Table26[[#This Row],[TOTAL STOCKS RECEIVED (QTY)]]-Table26[[#This Row],[TOTAL STOCKS RELEASED (QTY)]] -> 130.48 | G6: =IFERROR(VLOOKUP(B6,SUPPLY2,3,0),"-") -> C | H6: =IFERROR(VLOOKUP(B6,SUPPLY2,4,0),"-") -> 46 | I6: =IFERROR(VLOOKUP(A6,YEAR2023,2,0),"-") -> 0 | L6: 1
A7: =TODAY() -> 46223 | B7: Envelope - expanding 11x15x 2 w/out flap | D7: =SUMIFS('DATA ENTRY - RECEIVED'!F:F,'DATA ENTRY - RECEIVED'!E:E,"=Envelope - expanding 11x15x 2 w/out flap") -> 0 | E7: =SUMIFS('DATA ENTRY - RELEASED'!C:C,'DATA ENTRY - RELEASED'!B:B,"=Envelope - expanding 11x15x 2 w/out flap") -> 4 | F7: =Table26[[#This Row],[BEG BALANCE (QTY)]]+Table26[[#This Row],[TOTAL STOCKS RECEIVED (QTY)]]-Table26[[#This Row],[TOTAL STOCKS RELEASED (QTY)]] -> -4 | G7: =IFERROR(VLOOKUP(B7,SUPPLY2,3,0),"-") -> Piece | H7: =IFERROR(VLOOKUP(B7,SUPPLY2,4,0),"-") -> 59 | I7: =IFERROR(VLOOKUP(A7,YEAR2023,2,0),"-") -> 0
A8: =TODAY() -> 46223 | B8: Envelope - window reg mailing only white (500 pcs/box) | D8: =SUMIFS('DATA ENTRY - RECEIVED'!F:F,'DATA ENTRY - RECEIVED'!E:E,"=Envelope - window reg mailing only white (500 pcs/box)") -> 0 | E8: =SUMIFS('DATA ENTRY - RELEASED'!C:C,'DATA ENTRY - RELEASED'!B:B,"=Envelope - window reg mailing only white (500 pcs/box)") -> 0 | F8: =Table26[[#This Row],[BEG BALANCE (QTY)]]+Table26[[#This Row],[TOTAL STOCKS RECEIVED (QTY)]]-Table26[[#This Row],[TOTAL STOCKS RELEASED (QTY)]] -> 0 | G8: =IFERROR(VLOOKUP(B8,SUPPLY2,3,0),"-") -> Box | H8: =IFERROR(VLOOKUP(B8,SUPPLY2,4,0),"-") -> 40 | I8: =IFERROR(VLOOKUP(A8,YEAR2023,2,0),"-") -> 0
A9: =TODAY() -> 46223 | B9: Envelope-wdw reg no add white for brnchs (500 pcs/box) | D9: =SUMIFS('DATA ENTRY - RECEIVED'!F:F,'DATA ENTRY - RECEIVED'!E:E,"=Envelope-wdw reg no add white for brnchs (500 pcs/box)") -> 0 | E9: =SUMIFS('DATA ENTRY - RELEASED'!C:C,'DATA ENTRY - RELEASED'!B:B,"=Envelope-wdw reg no add white for brnchs (500 pcs/box)") -> 0 | F9: =Table26[[#This Row],[BEG BALANCE (QTY)]]+Table26[[#This Row],[TOTAL STOCKS RECEIVED (QTY)]]-Table26[[#This Row],[TOTAL STOCKS RELEASED (QTY)]] -> 0 | G9: =IFERROR(VLOOKUP(B9,SUPPLY2,3,0),"-") -> Box | H9: =IFERROR(VLOOKUP(B9,SUPPLY2,4,0),"-") -> 1695 | I9: =IFERROR(VLOOKUP(A9,YEAR2023,2,0),"-") -> 0
A10: =TODAY() -> 46223 | B10: Envelope, expanding kraftboard for legal docs. | D10: =SUMIFS('DATA ENTRY - RECEIVED'!F:F,'DATA ENTRY - RECEIVED'!E:E,"=Envelope, expanding kraftboard for legal docs.") -> 0 | E10: =SUMIFS('DATA ENTRY - RELEASED'!C:C,'DATA ENTRY - RELEASED'!B:B,"=Envelope, expanding kraftboard for legal docs.") -> 6 | F10: =Table26[[#This Row],[BEG BALANCE (QTY)]]+Table26[[#This Row],[TOTAL STOCKS RECEIVED (QTY)]]-Table26[[#This Row],[TOTAL STOCKS RELEASED (QTY)]] -> -6 | G10: =IFERROR(VLOOKUP(B10,SUPPLY2,3,0),"-") -> Piece | H10: =IFERROR(VLOOKUP(B10,SUPPLY2,4,0),"-") -> 2366 | I10: =IFERROR(VLOOKUP(A10,YEAR2023,2,0),"-") -> 0
A11: =TODAY() -> 46223 | B11: Folder - cardboard loose lift 8-1/2x14 | D11: =SUMIFS('DATA ENTRY - RECEIVED'!F:F,'DATA ENTRY - RECEIVED'!E:E,"=Folder - cardboard loose lift 8-1/2x14") -> 0 | E11: =SUMIFS('DATA ENTRY - RELEASED'!C:C,'DATA ENTRY - RELEASED'!B:B,"=Folder - cardboard loose lift 8-1/2x14") -> 0 | F11: =Table26[[#This Row],[BEG BALANCE (QTY)]]+Table26[[#This Row],[TOTAL STOCKS RECEIVED (QTY)]]-Table26[[#This Row],[TOTAL STOCKS RELEASED (QTY)]] -> 0 | G11: =IFERROR(VLOOKUP(B11,SUPPLY2,3,0),"-") -> Set | H11: =IFERROR(VLOOKUP(B11,SUPPLY2,4,0),"-") -> 331 | I11: =IFERROR(VLOOKUP(A11,YEAR2023,2,0),"-") -> 0
A12: =TODAY() -> 46223 | B12: Folder - legal size, 36mm thick (14pts) | C12: 2 | D12: =SUMIFS('DATA ENTRY - RECEIVED'!F:F,'DATA ENTRY - RECEIVED'!E:E,"=Folder - legal size, 36mm thick (14pts)") -> 143 | E12: =SUMIFS('DATA ENTRY - RELEASED'!C:C,'DATA ENTRY - RELEASED'!B:B,"=Folder - legal size, 36mm thick (14pts)") -> 315 | F12: =Table26[[#This Row],[BEG BALANCE (QTY)]]+Table26[[#This Row],[TOTAL STOCKS RECEIVED (QTY)]]-Table26[[#This Row],[TOTAL STOCKS RELEASED (QTY)]] -> -170 | G12: =IFERROR(VLOOKUP(B12,SUPPLY2,3,0),"-") -> C | H12: =IFERROR(VLOOKUP(B12,SUPPLY2,4,0),"-") -> 330 | I12: =IFERROR(VLOOKUP(A12,YEAR2023,2,0),"-") -> 0 | L12: 1
A13: =TODAY() -> 46223 | B13: Folder - marble green, 11 x 14-7/8 | D13: =SUMIFS('DATA ENTRY - RECEIVED'!F:F,'DATA ENTRY - RECEIVED'!E:E,"=Folder - marble green, 11 x 14-7/8") -> 0 | E13: =SUMIFS('DATA ENTRY - RELEASED'!C:C,'DATA ENTRY - RELEASED'!B:B,"=Folder - marble green, 11 x 14-7/8") -> 0 | F13: =Table26[[#This Row],[BEG BALANCE (QTY)]]+Table26[[#This Row],[TOTAL STOCKS RECEIVED (QTY)]]-Table26[[#This Row],[TOTAL STOCKS RELEASED (QTY)]] -> 0 | G13: =IFERROR(VLOOKUP(B13,SUPPLY2,3,0),"-") -> Set | H13: =IFERROR(VLOOKUP(B13,SUPPLY2,4,0),"-") -> 65 | I13: =IFERROR(VLOOKUP(A13,YEAR2023,2,0),"-") -> 0
A14: =TODAY() -> 46223 | B14: Paper - adding machine tape, 2-1/4 | D14: =SUMIFS('DATA ENTRY - RECEIVED'!F:F,'DATA ENTRY - RECEIVED'!E:E,"=Paper - adding machine tape, 2-1/4") -> 0 | E14: =SUMIFS('DATA ENTRY - RELEASED'!C:C,'DATA ENTRY - RELEASED'!B:B,"=Paper - adding machine tape, 2-1/4") -> 0 | F14: =Table26[[#This Row],[BEG BALANCE (QTY)]]+Table26[[#This Row],[TOTAL STOCKS RECEIVED (QTY)]]-Table26[[#This Row],[TOTAL STOCKS RELEASED (QTY)]] -> 0 | G14: =IFERROR(VLOOKUP(B14,SUPPLY2,3,0),"-") -> Piece | H14: =IFERROR(VLOOKUP(B14,SUPPLY2,4,0),"-") -> 70 | I14: =IFERROR(VLOOKUP(A14,YEAR2023,2,0),"-") -> 0
A15: =TODAY() -> 46223 | B15: Paper-bond w/letterhead, a4 size 70gsm | D15: =SUMIFS('DATA ENTRY - RECEIVED'!F:F,'DATA ENTRY - RECEIVED'!E:E,"=Paper-bond w/letterhead, a4 size 70gsm") -> 0 | E15: =SUMIFS('DATA ENTRY - RELEASED'!C:C,'DATA ENTRY - RELEASED'!B:B,"=Paper-bond w/letterhead, a4 size 70gsm") -> 0 | F15: =Table26[[#This Row],[BEG BALANCE (QTY)]]+Table26[[#This Row],[TOTAL STOCKS RECEIVED (QTY)]]-Table26[[#This Row],[TOTAL STOCKS RELEASED (QTY)]] -> 0 | G15: =IFERROR(VLOOKUP(B15,SUPPLY2,3,0),"-") -> Ream | H15: =IFERROR(VLOOKUP(B15,SUPPLY2,4,0),"-") -> 1823 | I15: =IFERROR(VLOOKUP(A15,YEAR2023,2,0),"-") -> 0
A16: =TODAY() -> 46223 | B16: UBP QUICK CARDS - PENSION LOAN | C16: 450 | D16: =SUMIFS('DATA ENTRY - RECEIVED'!F:F,'DATA ENTRY - RECEIVED'!E:E,"=UBP QUICK CARDS - PENSION LOAN") -> 0 | E16: =SUMIFS('DATA ENTRY - RELEASED'!C:C,'DATA ENTRY - RELEASED'!B:B,"=UBP QUICK CARDS - PENSION LOAN") -> 450 | F16: =Table26[[#This Row],[BEG BALANCE (QTY)]]+Table26[[#This Row],[TOTAL STOCKS RECEIVED (QTY)]]-Table26[[#This Row],[TOTAL STOCKS RELEASED (QTY)]] -> 0 | G16: =IFERROR(VLOOKUP(B16,SUPPLY2,3,0),"-") -> pc | H16: =IFERROR(VLOOKUP(B16,SUPPLY2,4,0),"-") -> UBP | I16: =IFERROR(VLOOKUP(A16,YEAR2023,2,0),"-") -> 0
A17: =TODAY() -> 46223 | B17: ACOP-PENSIONERS REPLY P1&2 | C17: 1 | D17: =SUMIFS('DATA ENTRY - RECEIVED'!F:F,'DATA ENTRY - RECEIVED'!E:E,"=ACOP-PENSIONERS REPLY P1&2") -> 0 | E17: =SUMIFS('DATA ENTRY - RELEASED'!C:C,'DATA ENTRY - RELEASED'!B:B,"=ACOP-PENSIONERS REPLY P1&2") -> 0 | F17: =Table26[[#This Row],[BEG BALANCE (QTY)]]+Table26[[#This Row],[TOTAL STOCKS RECEIVED (QTY)]]-Table26[[#This Row],[TOTAL STOCKS RELEASED (QTY)]] -> 1 | G17: =IFERROR(VLOOKUP(B17,SUPPLY2,3,0),"-") -> - | H17: =IFERROR(VLOOKUP(B17,SUPPLY2,4,0),"-") -> - | I17: =IFERROR(VLOOKUP(A17,YEAR2023,2,0),"-") -> 0
A18: =TODAY() -> 46223 | B18: DEATH CLAIM APPLICATION PAGE 1 | D18: =SUMIFS('DATA ENTRY - RECEIVED'!F:F,'DATA ENTRY - RECEIVED'!E:E,"=DEATH CLAIM APPLICATION PAGE 1") -> 0 | E18: =SUMIFS('DATA ENTRY - RELEASED'!C:C,'DATA ENTRY - RELEASED'!B:B,"=DEATH CLAIM APPLICATION PAGE 1") -> 0 | F18: =Table26[[#This Row],[BEG BALANCE (QTY)]]+Table26[[#This Row],[TOTAL STOCKS RECEIVED (QTY)]]-Table26[[#This Row],[TOTAL STOCKS RELEASED (QTY)]] -> 0 | G18: =IFERROR(VLOOKUP(B18,SUPPLY2,3,0),"-") -> - | H18: =IFERROR(VLOOKUP(B18,SUPPLY2,4,0),"-") -> - | I18: =IFERROR(VLOOKUP(A18,YEAR2023,2,0),"-") -> 0
A19: =TODAY() -> 46223 | B19: DEATH CLAIM APPLICATION PAGE 2 | D19: =SUMIFS('DATA ENTRY - RECEIVED'!F:F,'DATA ENTRY - RECEIVED'!E:E,"=DEATH CLAIM APPLICATION PAGE 2") -> 0 | E19: =SUMIFS('DATA ENTRY - RELEASED'!C:C,'DATA ENTRY - RELEASED'!B:B,"=DEATH CLAIM APPLICATION PAGE 2") -> 0 | F19: =Table26[[#This Row],[BEG BALANCE (QTY)]]+Table26[[#This Row],[TOTAL STOCKS RECEIVED (QTY)]]-Table26[[#This Row],[TOTAL STOCKS RELEASED (QTY)]] -> 0 | G19: =IFERROR(VLOOKUP(B19,SUPPLY2,3,0),"-") -> - | H19: =IFERROR(VLOOKUP(B19,SUPPLY2,4,0),"-") -> - | I19: =IFERROR(VLOOKUP(A19,YEAR2023,2,0),"-") -> 0
A20: =TODAY() -> 46223 | B20: MEMBER DATA CHANGE REQUEST PAGE 1&2 | C20: 185 | D20: =SUMIFS('DATA ENTRY - RECEIVED'!F:F,'DATA ENTRY - RECEIVED'!E:E,"=MEMBER DATA CHANGE REQUEST PAGE 1&2") -> 25 | E20: =SUMIFS('DATA ENTRY - RELEASED'!C:C,'DATA ENTRY - RELEASED'!B:B,"=MEMBER DATA CHANGE REQUEST PAGE 1&2") -> 8808 | F20: =Table26[[#This Row],[BEG BALANCE (QTY)]]+Table26[[#This Row],[TOTAL STOCKS RECEIVED (QTY)]]-Table26[[#This Row],[TOTAL STOCKS RELEASED (QTY)]] -> -8598 | I20: =IFERROR(VLOOKUP(A20,YEAR2023,2,0),"-") -> 0
A21: =TODAY() -> 46223 | B21: E4-PAGE 1-MEMBER DATA CHANGE PAGE 1 | C21: 50 | D21: =SUMIFS('DATA ENTRY - RECEIVED'!F:F,'DATA ENTRY - RECEIVED'!E:E,"=E4-PAGE 1-MEMBER DATA CHANGE PAGE 1") -> 0 | E21: =SUMIFS('DATA ENTRY - RELEASED'!C:C,'DATA ENTRY - RELEASED'!B:B,"=E4-PAGE 1-MEMBER DATA CHANGE PAGE 1") -> 140 | F21: =Table26[[#This Row],[BEG BALANCE (QTY)]]+Table26[[#This Row],[TOTAL STOCKS RECEIVED (QTY)]]-Table26[[#This Row],[TOTAL STOCKS RELEASED (QTY)]] -> -90 | G21: =IFERROR(VLOOKUP(B21,SUPPLY2,3,0),"-") -> - | H21: =IFERROR(VLOOKUP(B21,SUPPLY2,4,0),"-") -> - | I21: =IFERROR(VLOOKUP(A21,YEAR2023,2,0),"-") -> 0
A22: =TODAY() -> 46223 | B22: E4-PAGE 2-MEMBER DATA CHANGE PAGE 2 | C22: 1 | D22: =SUMIFS('DATA ENTRY - RECEIVED'!F:F,'DATA ENTRY - RECEIVED'!E:E,"=E4-PAGE 2-MEMBER DATA CHANGE PAGE 2") -> 0 | E22: =SUMIFS('DATA ENTRY - RELEASED'!C:C,'DATA ENTRY - RELEASED'!B:B,"=E4-PAGE 2-MEMBER DATA CHANGE PAGE 2") -> 0 | F22: =Table26[[#This Row],[BEG BALANCE (QTY)]]+Table26[[#This Row],[TOTAL STOCKS RECEIVED (QTY)]]-Table26[[#This Row],[TOTAL STOCKS RELEASED (QTY)]] -> 1 | G22: =IFERROR(VLOOKUP(B22,SUPPLY2,3,0),"-") -> - | H22: =IFERROR(VLOOKUP(B22,SUPPLY2,4,0),"-") -> - | I22: =IFERROR(VLOOKUP(A22,YEAR2023,2,0),"-") -> 0
A23: =TODAY() -> 46223 | B23: FUNERAL APPLICATION | C23: 0 | D23: 51 | E23: =SUMIFS('DATA ENTRY - RELEASED'!C:C,'DATA ENTRY - RELEASED'!B:B,"=FUNERAL APPLICATION") -> 1 | F23: =Table26[[#This Row],[BEG BALANCE (QTY)]]+Table26[[#This Row],[TOTAL STOCKS RECEIVED (QTY)]]-Table26[[#This Row],[TOTAL STOCKS RELEASED (QTY)]] -> 50 | G23: =IFERROR(VLOOKUP(B23,SUPPLY2,3,0),"-") -> Ream | H23: =IFERROR(VLOOKUP(B23,SUPPLY2,4,0),"-") -> 1544 | I23: =IFERROR(VLOOKUP(A23,YEAR2023,2,0),"-") -> 0
